Workbook

Sheet Game Log Season 1
A1: Base Game Info | F1: Player Score | P1: Turn of Victory/Loss | R1: Pop-Off | S1: Deck Resilience | V1: Games Clearly Behind | W1: Game Calculated Deck Strength
A2: Game Date | B2: Game # | C2: Player Name | D2: Commander | E2: Commander Strength | F2: Game Result | G2: Place | H2: Pod Size | I2: Knockouts | J2: Adjusted Pod Size Win/Loss Score | K2: Knockout Score | L2: Deck Strength Comparison Differential | M2: Win Probability based on Deck Strength | N2: Player Score | O2: Normalized Player Score | P2: TOV | Q2: Normalized TOV | R2: Pop-Off | S2: Disruptions | T2: Successful Recoveries | U2: Deck Resilience Score | V2: Games Clearly Behind | W2: Game Calculated Deck Strength
A3: 46023 | B3: 1 | C3: Becca | D3: Aminatou, Veil Piercer | E3: 4 | F3: 0 | G3: 2 | H3: 4 | I3: 0 | J3: =F3-(1/H3) | K3: =((I3-((H3-1)/H3))-(-5/6))/((5-(5/6))-(-5/6)) | L3: =E3-((E4+E5+E6)/3) | M3: =0.5 + (L3 * 0.09) | N3: =((H3-(G3-1))/H3)*(IF(I3<>0,(I3+H3)/H3,1)) | O3: =(N3-(1/6))/(10/6) | P3: 8 | Q3: =IF(F3=1,(((1-((P3-3)/12))*0.5)+0.5),((P3/15)*0.5)) | R3: 0 | S3: 0 | T3: 0 | U3: =IFERROR(T3/S3, 1) | V3: 0 | W3: =5*((O3*0.3)+(Q3*0.175)+(R3*0.175)+(U3*0.175)+((1-V3)*0.175))
A4: 46023 | B4: 1 | C4: Manny | D4: Rashmi, Eternities Crafter | E4: 3 | F4: 0 | G4: 3 | H4: 4 | I4: 0 | J4: =F4-(1/H4) | K4: =((I4-((H4-1)/H4))-(-5/6))/((5-(5/6))-(-5/6)) | L4: =E4-((E3+E5+E6)/3) | M4: =0.5 + (L4 * 0.09) | N4: =((H4-(G4-1))/H4)*(IF(I4<>0,(I4+H4)/H4,1)) | O4: =(N4-(1/6))/(10/6) | P4: 7 | Q4: =IF(F4=1,(((1-((P4-3)/12))*0.5)+0.5),((P4/15)*0.5)) | R4: 0 | S4: 0 | T4: 0 | U4: =IFERROR(T4/S4, 1) | V4: 0 | W4: =5*((O4*0.3)+(Q4*0.175)+(R4*0.175)+(U4*0.175)+((1-V4)*0.175))
A5: 46023 | B5: 1 | C5: Mateo | D5: Zurgo Stormrender | E5: 2 | F5: 1 | G5: 1 | H5: 4 | I5: 3 | J5: =F5-(1/H5) | K5: =((I5-((H5-1)/H5))-(-5/6))/((5-(5/6))-(-5/6)) | L5: =E5-((E3+E4+E6)/3) | M5: =0.5 + (L5 * 0.09) | N5: =((H5-(G5-1))/H5)*(IF(I5<>0,(I5+H5)/H5,1)) | O5: =(N5-(1/6))/(10/6) | P5: 8 | Q5: =IF(F5=1,(((1-((P5-3)/12))*0.5)+0.5),((P5/15)*0.5)) | R5: 1 | S5: 1 | T5: 1 | U5: =IFERROR(T5/S5, 1) | V5: 0 | W5: =5*((O5*0.3)+(Q5*0.175)+(R5*0.175)+(U5*0.175)+((1-V5)*0.175))
A6: 46023 | B6: 1 | C6: Ryan | D6: Cloud, Ex-SOLDIER | E6: 2 | F6: 0 | G6: 4 | H6: 4 | I6: 0 | J6: =F6-(1/H6) | K6: =((I6-((H6-1)/H6))-(-5/6))/((5-(5/6))-(-5/6)) | L6: =E6-((E3+E4+E5)/3) | M6: =0.5 + (L6 * 0.09) | N6: =((H6-(G6-1))/H6)*(IF(I6<>0,(I6+H6)/H6,1)) | O6: =(N6-(1/6))/(10/6) | P6: 7 | Q6: =IF(F6=1,(((1-((P6-3)/12))*0.5)+0.5),((P6/15)*0.5)) | R6: 1 | S6: 0 | T6: 0 | U6: =IFERROR(T6/S6, 1) | V6: 0 | W6: =5*((O6*0.3)+(Q6*0.175)+(R6*0.175)+(U6*0.175)+((1-V6)*0.175))
A7: 46023 | B7: 2 | C7: Becca | D7: Aminatou, Veil Piercer | E7: 4 | F7: 0 | G7: 2 | H7: 4 | I7: 0 | J7: =F7-(1/H7) | K7: =((I7-((H7-1)/H7))-(-5/6))/((5-(5/6))-(-5/6)) | L7: =E7-((E8+E9+E10)/3) | M7: =0.5 + (L7 * 0.09) | N7: =((H7-(G7-1))/H7)*(IF(I7<>0,(I7+H7)/H7,1)) | O7: =(N7-(1/6))/(10/6) | P7: 8 | Q7: =IF(F7=1,(((1-((P7-3)/12))*0.5)+0.5),((P7/15)*0.5)) | R7: 0 | S7: 0 | T7: 0 | U7: =IFERROR(T7/S7, 1) | V7: 0 | W7: =5*((O7*0.3)+(Q7*0.175)+(R7*0.175)+(U7*0.175)+((1-V7)*0.175))
A8: 46023 | B8: 2 | C8: Manny | D8: Fire Lord Azula | E8: 3 | F8: 0 | G8: 2 | H8: 4 | I8: 0 | J8: =F8-(1/H8) | K8: =((I8-((H8-1)/H8))-(-5/6))/((5-(5/6))-(-5/6)) | L8: =E8-((E7+E9+E10)/3) | M8: =0.5 + (L8 * 0.09) | N8: =((H8-(G8-1))/H8)*(IF(I8<>0,(I8+H8)/H8,1)) | O8: =(N8-(1/6))/(10/6) | P8: 8 | Q8: =IF(F8=1,(((1-((P8-3)/12))*0.5)+0.5),((P8/15)*0.5)) | R8: 1 | S8: 0 | T8: 0 | U8: =IFERROR(T8/S8, 1) | V8: 0 | W8: =5*((O8*0.3)+(Q8*0.175)+(R8*0.175)+(U8*0.175)+((1-V8)*0.175))
A9: 46023 | B9: 2 | C9: Mateo | D9: Hazel of the Rootbloom | E9: 2 | F9: 0 | G9: 2 | H9: 4 | I9: 0 | J9: =F9-(1/H9) | K9: =((I9-((H9-1)/H9))-(-5/6))/((5-(5/6))-(-5/6)) | L9: =E9-((E7+E8+E10)/3) | M9: =0.5 + (L9 * 0.09) | N9: =((H9-(G9-1))/H9)*(IF(I9<>0,(I9+H9)/H9,1)) | O9: =(N9-(1/6))/(10/6) | P9: 8 | Q9: =IF(F9=1,(((1-((P9-3)/12))*0.5)+0.5),((P9/15)*0.5)) | R9: 0 | S9: 0 | T9: 0 | U9: =IFERROR(T9/S9, 1) | V9: 0 | W9: =5*((O9*0.3)+(Q9*0.175)+(R9*0.175)+(U9*0.175)+((1-V9)*0.175))
A10: 46023 | B10: 2 | C10: Ryan | D10: Eowyn, Shieldmaiden | E10: 2 | F10: 1 | G10: 1 | H10: 4 | I10: 3 | J10: =F10-(1/H10) | K10: =((I10-((H10-1)/H10))-(-5/6))/((5-(5/6))-(-5/6)) | L10: =E10-((E7+E8+E9)/3) | M10: =0.5 + (L10 * 0.09) | N10: =((H10-(G10-1))/H10)*(IF(I10<>0,(I10+H10)/H10,1)) | O10: =(N10-(1/6))/(10/6) | P10: 8 | Q10: =IF(F10=1,(((1-((P10-3)/12))*0.5)+0.5),((P10/15)*0.5)) | R10: 1 | S10: 0 | T10: 0 | U10: =IFERROR(T10/S10, 1) | V10: 0 | W10: =5*((O10*0.3)+(Q10*0.175)+(R10*0.175)+(U10*0.175)+((1-V10)*0.175))
A11: 46029 | B11: 3 | C11: Manny | D11: Aragorn, the Uniter | E11: 3 | F11: 1 | G11: 1 | H11: 4 | I11: 3 | J11: =F11-(1/H11) | K11: =((I11-((H11-1)/H11))-(-5/6))/((5-(5/6))-(-5/6)) | L11: =E11-((E12+E13+E14)/3) | M11: =0.5 + (L11 * 0.09) | N11: =((H11-(G11-1))/H11)*(IF(I11<>0,(I11+H11)/H11,1)) | O11: =(N11-(1/6))/(10/6) | P11: 12 | Q11: =IF(F11=1,(((1-((P11-3)/12))*0.5)+0.5),((P11/15)*0.5)) | R11: 1 | S11: 1 | T11: 1 | U11: =IFERROR(T11/S11, 1) | V11: 0 | W11: =5*((O11*0.3)+(Q11*0.175)+(R11*0.175)+(U11*0.175)+((1-V11)*0.175))
A12: 46029 | B12: 3 | C12: Joseph | D12: Mr. House, President and CEO | E12: 2 | F12: 0 | G12: 2 | H12: 4 | I12: 0 | J12: =F12-(1/H12) | K12: =((I12-((H12-1)/H12))-(-5/6))/((5-(5/6))-(-5/6)) | L12: =E12-((E11+E13+E14)/3) | M12: =0.5 + (L12 * 0.09) | N12: =((H12-(G12-1))/H12)*(IF(I12<>0,(I12+H12)/H12,1)) | O12: =(N12-(1/6))/(10/6) | P12: 12 | Q12: =IF(F12=1,(((1-((P12-3)/12))*0.5)+0.5),((P12/15)*0.5)) | R12: 0 | S12: 2 | T12: 0 | U12: =IFERROR(T12/S12, 1) | V12: 1 | W12: =5*((O12*0.3)+(Q12*0.175)+(R12*0.175)+(U12*0.175)+((1-V12)*0.175))
A13: 46029 | B13: 3 | C13: Mateo | D13: Chatterfang, Squirrel General | E13: 2 | F13: 0 | G13: 4 | H13: 4 | I13: 0 | J13: =F13-(1/H13) | K13: =((I13-((H13-1)/H13))-(-5/6))/((5-(5/6))-(-5/6)) | L13: =E13-((E11+E12+E14)/3) | M13: =0.5 + (L13 * 0.09) | N13: =((H13-(G13-1))/H13)*(IF(I13<>0,(I13+H13)/H13,1)) | O13: =(N13-(1/6))/(10/6) | P13: 7 | Q13: =IF(F13=1,(((1-((P13-3)/12))*0.5)+0.5),((P13/15)*0.5)) | R13: 1 | S13: 1 | T13: 0 | U13: =IFERROR(T13/S13, 1) | V13: 0 | W13: =5*((O13*0.3)+(Q13*0.175)+(R13*0.175)+(U13*0.175)+((1-V13)*0.175))
A14: 46029 | B14: 3 | C14: Ryan | D14: Fire Lord Zuko | E14: 3 | F14: 0 | G14: 3 | H14: 4 | I14: 0 | J14: =F14-(1/H14) | K14: =((I14-((H14-1)/H14))-(-5/6))/((5-(5/6))-(-5/6)) | L14: =E14-((E11+E12+E13)/3) | M14: =0.5 + (L14 * 0.09) | N14: =((H14-(G14-1))/H14)*(IF(I14<>0,(I14+H14)/H14,1)) | O14: =(N14-(1/6))/(10/6) | P14: 8 | Q14: =IF(F14=1,(((1-((P14-3)/12))*0.5)+0.5),((P14/15)*0.5)) | R14: 0 | S14: 0 | T14: 0 | U14: =IFERROR(T14/S14, 1) | V14: 0 | W14: =5*((O14*0.3)+(Q14*0.175)+(R14*0.175)+(U14*0.175)+((1-V14)*0.175))
A15: 46032 | B15: 4 | C15: Ryan | D15: Atraxa, Praetor's Voice | E15: 4 | F15: 1 | G15: 1 | H15: 2 | I15: 1 | J15: =F15-(1/H15) | K15: =((I15-((H15-1)/H15))-(-5/6))/((5-(5/6))-(-5/6)) | L15: =E15-E16 | M15: =0.5 + (L15 * 0.09) | N15: =((H15-(G15-1))/H15)*(IF(I15<>0,(I15+H15)/H15,1)) | O15: =(N15-(1/6))/(10/6) | P15: 10 | Q15: =IF(F15=1,(((1-((P15-3)/12))*0.5)+0.5),((P15/15)*0.5)) | R15: 1 | S15: 1 | T15: 1 | U15: =IFERROR(T15/S15, 1) | V15: 0 | W15: =5*((O15*0.3)+(Q15*0.175)+(R15*0.175)+(U15*0.175)+((1-V15)*0.175))
A16: 46032 | B16: 4 | C16: Manny | D16: Rashmi, Eternities Crafter | E16: 3 | F16: 0 | G16: 2 | H16: 2 | I16: 0 | J16: =F16-(1/H16) | K16: =((I16-((H16-1)/H16))-(-5/6))/((5-(5/6))-(-5/6)) | L16: =E16-E15 | M16: =0.5 + (L16 * 0.09) | N16: =((H16-(G16-1))/H16)*(IF(I16<>0,(I16+H16)/H16,1)) | O16: =(N16-(1/6))/(10/6) | P16: 10 | Q16: =IF(F16=1,(((1-((P16-3)/12))*0.5)+0.5),((P16/15)*0.5)) | R16: 1 | S16: 0 | T16: 0 | U16: =IFERROR(T16/S16, 1) | V16: 0 | W16: =5*((O16*0.3)+(Q16*0.175)+(R16*0.175)+(U16*0.175)+((1-V16)*0.175))
A17: 46032 | B17: 5 | C17: Ryan | D17: Davros, Dalek Creator | E17: 2 | F17: 0 | G17: 3 | H17: 4 | I17: 0 | J17: =F17-(1/H17) | K17: =((I17-((H17-1)/H17))-(-5/6))/((5-(5/6))-(-5/6)) | L17: =E17-((E18+E19+E20)/3) | M17: =0.5 + (L17 * 0.09) | N17: =((H17-(G17-1))/H17)*(IF(I17<>0,(I17+H17)/H17,1)) | O17: =(N17-(1/6))/(10/6) | P17: 12 | Q17: =IF(F17=1,(((1-((P17-3)/12))*0.5)+0.5),((P17/15)*0.5)) | R17: 1 | S17: 1 | T17: 1 | U17: =IFERROR(T17/S17, 1) | V17: 0 | W17: =5*((O17*0.3)+(Q17*0.175)+(R17*0.175)+(U17*0.175)+((1-V17)*0.175))
A18: 46032 | B18: 5 | C18: Manny | D18: Frodo, Adventurous Hobbit/Sam, Loyal Attendant | E18: 4 | F18: 0 | G18: 2 | H18: 4 | I18: 2 | J18: =F18-(1/H18) | K18: =((I18-((H18-1)/H18))-(-5/6))/((5-(5/6))-(-5/6)) | L18: =E18-((E17+E19+E20)/3) | M18: =0.5 + (L18 * 0.09) | N18: =((H18-(G18-1))/H18)*(IF(I18<>0,(I18+H18)/H18,1)) | O18: =(N18-(1/6))/(10/6) | P18: 12 | Q18: =IF(F18=1,(((1-((P18-3)/12))*0.5)+0.5),((P18/15)*0.5)) | R18: 1 | S18: 1 | T18: 1 | U18: =IFERROR(T18/S18, 1) | V18: 0 | W18: =5*((O18*0.3)+(Q18*0.175)+(R18*0.175)+(U18*0.175)+((1-V18)*0.175))
A19: 46032 | B19: 5 | C19: Becca | D19: Ms. Bumbleflower | E19: 2 | F19: 1 | G19: 1 | H19: 4 | I19: 1 | J19: =F19-(1/H19) | K19: =((I19-((H19-1)/H19))-(-5/6))/((5-(5/6))-(-5/6)) | L19: =E19-((E17+E18+E20)/3) | M19: =0.5 + (L19 * 0.09) | N19: =((H19-(G19-1))/H19)*(IF(I19<>0,(I19+H19)/H19,1)) | O19: =(N19-(1/6))/(10/6) | P19: 12 | Q19: =IF(F19=1,(((1-((P19-3)/12))*0.5)+0.5),((P19/15)*0.5)) | R19: 1 | S19: 2 | T19: 2 | U19: =IFERROR(T19/S19, 1) | V19: 0 | W19: =5*((O19*0.3)+(Q19*0.175)+(R19*0.175)+(U19*0.175)+((1-V19)*0.175))
A20: 46032 | B20: 5 | C20: Mateo | D20: Teval, the Balanced Scale | E20: 2 | F20: 0 | G20: 4 | H20: 4 | I20: 0 | J20: =F20-(1/H20) | K20: =((I20-((H20-1)/H20))-(-5/6))/((5-(5/6))-(-5/6)) | L20: =E20-((E17+E18+E19)/3) | M20: =0.5 + (L20 * 0.09) | N20: =((H20-(G20-1))/H20)*(IF(I20<>0,(I20+H20)/H20,1)) | O20: =(N20-(1/6))/(10/6) | P20: 11 | Q20: =IF(F20=1,(((1-((P20-3)/12))*0.5)+0.5),((P20/15)*0.5)) | R20: 1 | S20: 1 | T20: 1 | U20: =IFERROR(T20/S20, 1) | V20: 0 | W20: =5*((O20*0.3)+(Q20*0.175)+(R20*0.175)+(U20*0.175)+((1-V20)*0.175))
A21: 46032 | B21: 6 | C21: Becca | D21: Aminatou, Veil Piercer | E21: 4 | F21: 0 | G21: 4 | H21: 4 | I21: 0 | J21: =F21-(1/H21) | K21: =((I21-((H21-1)/H21))-(-5/6))/((5-(5/6))-(-5/6)) | L21: =E21-((E22+E23+E24)/3) | M21: =0.5 + (L21 * 0.09) | N21: =((H21-(G21-1))/H21)*(IF(I21<>0,(I21+H21)/H21,1)) | O21: =(N21-(1/6))/(10/6) | P21: 8 | Q21: =IF(F21=1,(((1-((P21-3)/12))*0.5)+0.5),((P21/15)*0.5)) | R21: 0 | S21: 0 | T21: 0 | U21: =IFERROR(T21/S21, 1) | V21: 0 | W21: =5*((O21*0.3)+(Q21*0.175)+(R21*0.175)+(U21*0.175)+((1-V21)*0.175))
A22: 46032 | B22: 6 | C22: Ryan | D22: Cloud, Ex-SOLDIER | E22: 2 | F22: 0 | G22: 3 | H22: 4 | I22: 1 | J22: =F22-(1/H22) | K22: =((I22-((H22-1)/H22))-(-5/6))/((5-(5/6))-(-5/6)) | L22: =E22-((E21+E23+E24)/3) | M22: =0.5 + (L22 * 0.09) | N22: =((H22-(G22-1))/H22)*(IF(I22<>0,(I22+H22)/H22,1)) | O22: =(N22-(1/6))/(10/6) | P22: 9 | Q22: =IF(F22=1,(((1-((P22-3)/12))*0.5)+0.5),((P22/15)*0.5)) | R22: 1 | S22: 1 | T22: 0 | U22: =IFERROR(T22/S22, 1) | V22: 0 | W22: =5*((O22*0.3)+(Q22*0.175)+(R22*0.175)+(U22*0.175)+((1-V22)*0.175))
A23: 46032 | B23: 6 | C23: Manny | D23: Avatar Aang | E23: 3 | F23: 0 | G23: 2 | H23: 4 | I23: 0 | J23: =F23-(1/H23) | K23: =((I23-((H23-1)/H23))-(-5/6))/((5-(5/6))-(-5/6)) | L23: =E23-((E21+E22+E24)/3) | M23: =0.5 + (L23 * 0.09) | N23: =((H23-(G23-1))/H23)*(IF(I23<>0,(I23+H23)/H23,1)) | O23: =(N23-(1/6))/(10/6) | P23: 9 | Q23: =IF(F23=1,(((1-((P23-3)/12))*0.5)+0.5),((P23/15)*0.5)) | R23: 0 | S23: 1 | T23: 0 | U23: =IFERROR(T23/S23, 1) | V23: 0 | W23: =5*((O23*0.3)+(Q23*0.175)+(R23*0.175)+(U23*0.175)+((1-V23)*0.175))
A24: 46032 | B24: 6 | C24: Mateo | D24: Ureni of the Unwritten | E24: 3 | F24: 1 | G24: 1 | H24: 4 | I24: 2 | J24: =F24-(1/H24) | K24: =((I24-((H24-1)/H24))-(-5/6))/((5-(5/6))-(-5/6)) | L24: =E24-((E21+E22+E23)/3) | M24: =0.5 + (L24 * 0.09) | N24: =((H24-(G24-1))/H24)*(IF(I24<>0,(I24+H24)/H24,1)) | O24: =(N24-(1/6))/(10/6) | P24: 9 | Q24: =IF(F24=1,(((1-((P24-3)/12))*0.5)+0.5),((P24/15)*0.5)) | R24: 1 | S24: 0 | T24: 0 | U24: =IFERROR(T24/S24, 1) | V24: 0 | W24: =5*((O24*0.3)+(Q24*0.175)+(R24*0.175)+(U24*0.175)+((1-V24)*0.175))
A25: 46036 | B25: 7 | C25: Joseph | D25: Valgavoth, Harrower of Souls | E25: 3 | F25: 0 | G25: 2 | H25: 4 | I25: 1 | J25: =F25-(1/H25) | K25: =((I25-((H25-1)/H25))-(-5/6))/((5-(5/6))-(-5/6)) | L25: =E25-((E26+E27+E28)/3) | M25: =0.5 + (L25 * 0.09) | N25: =((H25-(G25-1))/H25)*(IF(I25<>0,(I25+H25)/H25,1)) | O25: =(N25-(1/6))/(10/6) | P25: 10 | Q25: =IF(F25=1,(((1-((P25-3)/12))*0.5)+0.5),((P25/15)*0.5)) | R25: 0 | S25: 1 | T25: 0 | U25: =IFERROR(T25/S25, 1) | V25: 0 | W25: =5*((O25*0.3)+(Q25*0.175)+(R25*0.175)+(U25*0.175)+((1-V25)*0.175))
A26: 46036 | B26: 7 | C26: Manny | D26: Avatar Aang | E26: 3 | F26: 0 | G26: 2 | H26: 4 | I26: 0 | J26: =F26-(1/H26) | K26: =((I26-((H26-1)/H26))-(-5/6))/((5-(5/6))-(-5/6)) | L26: =E26-((E25+E27+E28)/3) | M26: =0.5 + (L26 * 0.09) | N26: =((H26-(G26-1))/H26)*(IF(I26<>0,(I26+H26)/H26,1)) | O26: =(N26-(1/6))/(10/6) | P26: 10 | Q26: =IF(F26=1,(((1-((P26-3)/12))*0.5)+0.5),((P26/15)*0.5)) | R26: 0 | S26: 1 | T26: 0 | U26: =IFERROR(T26/S26, 1) | V26: 0 | W26: =5*((O26*0.3)+(Q26*0.175)+(R26*0.175)+(U26*0.175)+((1-V26)*0.175))
A27: 46036 | B27: 7 | C27: Ryan | D27: Eowyn, Shieldmaiden | E27: 2 | F27: 1 | G27: 1 | H27: 4 | I27: 2 | J27: =F27-(1/H27) | K27: =((I27-((H27-1)/H27))-(-5/6))/((5-(5/6))-(-5/6)) | L27: =E27-((E25+E26+E28)/3) | M27: =0.5 + (L27 * 0.09) | N27: =((H27-(G27-1))/H27)*(IF(I27<>0,(I27+H27)/H27,1)) | O27: =(N27-(1/6))/(10/6) | P27: 10 | Q27: =IF(F27=1,(((1-((P27-3)/12))*0.5)+0.5),((P27/15)*0.5)) | R27: 1 | S27: 2 | T27: 1 | U27: =IFERROR(T27/S27, 1) | V27: 0 | W27: =5*((O27*0.3)+(Q27*0.175)+(R27*0.175)+(U27*0.175)+((1-V27)*0.175))
A28: 46036 | B28: 7 | C28: Mateo | D28: Teval, the Balanced Scale | E28: 2 | F28: 0 | G28: 4 | H28: 4 | I28: 0 | J28: =F28-(1/H28) | K28: =((I28-((H28-1)/H28))-(-5/6))/((5-(5/6))-(-5/6)) | L28: =E28-((E25+E26+E27)/3) | M28: =0.5 + (L28 * 0.09) | N28: =((H28-(G28-1))/H28)*(IF(I28<>0,(I28+H28)/H28,1)) | O28: =(N28-(1/6))/(10/6) | P28: 9 | Q28: =IF(F28=1,(((1-((P28-3)/12))*0.5)+0.5),((P28/15)*0.5)) | R28: 1 | S28: 1 | T28: 1 | U28: =IFERROR(T28/S28, 1) | V28: 0 | W28: =5*((O28*0.3)+(Q28*0.175)+(R28*0.175)+(U28*0.175)+((1-V28)*0.175))
A29: 46038 | B29: 8 | C29: Mateo | D29: Toph, The First Metalbender | E29: 3 | F29: 1 | G29: 1 | H29: 4 | I29: 3 | J29: =F29-(1/H29) | K29: =((I29-((H29-1)/H29))-(-5/6))/((5-(5/6))-(-5/6)) | L29: =E29-((E30+E31+E32)/3) | M29: =0.5 + (L29 * 0.09) | N29: =((H29-(G29-1))/H29)*(IF(I29<>0,(I29+H29)/H29,1)) | O29: =(N29-(1/6))/(10/6) | P29: 9 | Q29: =IF(F29=1,(((1-((P29-3)/12))*0.5)+0.5),((P29/15)*0.5)) | R29: 1 | S29: 0 | T29: 0 | U29: =IFERROR(T29/S29, 1) | V29: 0 | W29: =5*((O29*0.3)+(Q29*0.175)+(R29*0.175)+(U29*0.175)+((1-V29)*0.175))
A30: 46038 | B30: 8 | C30: Ryan | D30: Fire Lord Zuko | E30: 3 | F30: 0 | G30: 2 | H30: 4 | I30: 0 | J30: =F30-(1/H30) | K30: =((I30-((H30-1)/H30))-(-5/6))/((5-(5/6))-(-5/6)) | L30: =E30-((E29+E31+E32)/3) | M30: =0.5 + (L30 * 0.09) | N30: =((H30-(G30-1))/H30)*(IF(I30<>0,(I30+H30)/H30,1)) | O30: =(N30-(1/6))/(10/6) | P30: 9 | Q30: =IF(F30=1,(((1-((P30-3)/12))*0.5)+0.5),((P30/15)*0.5)) | R30: 0 | S30: 0 | T30: 0 | U30: =IFERROR(T30/S30, 1) | V30: 0 | W30: =5*((O30*0.3)+(Q30*0.175)+(R30*0.175)+(U30*0.175)+((1-V30)*0.175))
A31: 46038 | B31: 8 | C31: Becca | D31: Aminatou, Veil Piercer | E31: 4 | F31: 0 | G31: 3 | H31: 4 | I31: 0 | J31: =F31-(1/H31) | K31: =((I31-((H31-1)/H31))-(-5/6))/((5-(5/6))-(-5/6)) | L31: =E31-((E29+E30+E32)/3) | M31: =0.5 + (L31 * 0.09) | N31: =((H31-(G31-1))/H31)*(IF(I31<>0,(I31+H31)/H31,1)) | O31: =(N31-(1/6))/(10/6) | P31: 9 | Q31: =IF(F31=1,(((1-((P31-3)/12))*0.5)+0.5),((P31/15)*0.5)) | R31: 0 | S31: 0 | T31: 0 | U31: =IFERROR(T31/S31, 1) | V31: 0 | W31: =5*((O31*0.3)+(Q31*0.175)+(R31*0.175)+(U31*0.175)+((1-V31)*0.175))
A32: 46038 | B32: 8 | C32: Manny | D32: Rashmi, Eternities Crafter | E32: 3 | F32: 0 | G32: 4 | H32: 4 | I32: 0 | J32: =F32-(1/H32) | K32: =((I32-((H32-1)/H32))-(-5/6))/((5-(5/6))-(-5/6)) | L32: =E32-((E29+E30+E31)/3) | M32: =0.5 + (L32 * 0.09) | N32: =((H32-(G32-1))/H32)*(IF(I32<>0,(I32+H32)/H32,1)) | O32: =(N32-(1/6))/(10/6) | P32: 9 | Q32: =IF(F32=1,(((1-((P32-3)/12))*0.5)+0.5),((P32/15)*0.5)) | R32: 0 | S32: 0 | T32: 0 | U32: =IFERROR(T32/S32, 1) | V32: 0 | W32: =5*((O32*0.3)+(Q32*0.175)+(R32*0.175)+(U32*0.175)+((1-V32)*0.175))
A33: 46038 | B33: 9 | C33: Manny | D33: Rashmi, Eternities Crafter | E33: 3 | F33: 1 | G33: 1 | H33: 3 | I33: 1 | J33: =F33-(1/H33) | K33: =((I33-((H33-1)/H33))-(-5/6))/((5-(5/6))-(-5/6)) | L33: =E33-((E34+E35)/2) | M33: =0.5 + (L33 * 0.09) | N33: =((H33-(G33-1))/H33)*(IF(I33<>0,(I33+H33)/H33,1)) | O33: =(N33-(1/6))/(10/6) | P33: 12 | Q33: =IF(F33=1,(((1-((P33-3)/12))*0.5)+0.5),((P33/15)*0.5)) | R33: 1 | S33: 0 | T33: 0 | U33: =IFERROR(T33/S33, 1) | V33: 0 | W33: =5*((O33*0.3)+(Q33*0.175)+(R33*0.175)+(U33*0.175)+((1-V33)*0.175))
A34: 46038 | B34: 9 | C34: Ryan | D34: Atraxa, Praetor's Voice | E34: 4 | F34: 0 | G34: 2 | H34: 3 | I34: 1 | J34: =F34-(1/H34) | K34: =((I34-((H34-1)/H34))-(-5/6))/((5-(5/6))-(-5/6)) | L34: =E34-((E33+E35)/2) | M34: =0.5 + (L34 * 0.09) | N34: =((H34-(G34-1))/H34)*(IF(I34<>0,(I34+H34)/H34,1)) | O34: =(N34-(1/6))/(10/6) | P34: 12 | Q34: =IF(F34=1,(((1-((P34-3)/12))*0.5)+0.5),((P34/15)*0.5)) | R34: 1 | S34: 2 | T34: 0 | U34: =IFERROR(T34/S34, 1) | V34: 0 | W34: =5*((O34*0.3)+(Q34*0.175)+(R34*0.175)+(U34*0.175)+((1-V34)*0.175))
A35: 46038 | B35: 9 | C35: Mateo | D35: Zurgo Stormrender | E35: 2 | F35: 0 | G35: 3 | H35: 3 | I35: 0 | J35: =F35-(1/H35) | K35: =((I35-((H35-1)/H35))-(-5/6))/((5-(5/6))-(-5/6)) | L35: =E35-((E33+E34)/2) | M35: =0.5 + (L35 * 0.09) | N35: =((H35-(G35-1))/H35)*(IF(I35<>0,(I35+H35)/H35,1)) | O35: =(N35-(1/6))/(10/6) | P35: 9 | Q35: =IF(F35=1,(((1-((P35-3)/12))*0.5)+0.5),((P35/15)*0.5)) | R35: 1 | S35: 1 | T35: 0 | U35: =IFERROR(T35/S35, 1) | V35: 0 | W35: =5*((O35*0.3)+(Q35*0.175)+(R35*0.175)+(U35*0.175)+((1-V35)*0.175))
A36: 46039 | B36: 10 | C36: Ryan | D36: Fire Lord Zuko | E36: 3 | F36: 1 | G36: 1 | H36: 3 | I36: 2 | J36: =F36-(1/H36) | K36: =((I36-((H36-1)/H36))-(-5/6))/((5-(5/6))-(-5/6)) | L36: =E36-((E37+E38)/2) | M36: =0.5 + (L36 * 0.09) | N36: =((H36-(G36-1))/H36)*(IF(I36<>0,(I36+H36)/H36,1)) | O36: =(N36-(1/6))/(10/6) | P36: 7 | Q36: =IF(F36=1,(((1-((P36-3)/12))*0.5)+0.5),((P36/15)*0.5)) | R36: 1 | S36: 0 | T36: 0 | U36: =IFERROR(T36/S36, 1) | V36: 0 | W36: =5*((O36*0.3)+(Q36*0.175)+(R36*0.175)+(U36*0.175)+((1-V36)*0.175))
A37: 46039 | B37: 10 | C37: Michelle | D37: The Wise Mothman | E37: 2 | F37: 0 | G37: 2 | H37: 3 | I37: 0 | J37: =F37-(1/H37) | K37: =((I37-((H37-1)/H37))-(-5/6))/((5-(5/6))-(-5/6)) | L37: =E37-((E36+E38)/2) | M37: =0.5 + (L37 * 0.09) | N37: =((H37-(G37-1))/H37)*(IF(I37<>0,(I37+H37)/H37,1)) | O37: =(N37-(1/6))/(10/6) | P37: 7 | Q37: =IF(F37=1,(((1-((P37-3)/12))*0.5)+0.5),((P37/15)*0.5)) | R37: 0 | S37: 0 | T37: 0 | U37: =IFERROR(T37/S37, 1) | V37: 0 | W37: =5*((O37*0.3)+(Q37*0.175)+(R37*0.175)+(U37*0.175)+((1-V37)*0.175))
A38: 46039 | B38: 10 | C38: Mateo | D38: Teval, the Balanced Scale | E38: 2 | F38: 0 | G38: 2 | H38: 3 | I38: 0 | J38: =F38-(1/H38) | K38: =((I38-((H38-1)/H38))-(-5/6))/((5-(5/6))-(-5/6)) | L38: =E38-((E36+E37)/2) | M38: =0.5 + (L38 * 0.09) | N38: =((H38-(G38-1))/H38)*(IF(I38<>0,(I38+H38)/H38,1)) | O38: =(N38-(1/6))/(10/6) | P38: 7 | Q38: =IF(F38=1,(((1-((P38-3)/12))*0.5)+0.5),((P38/15)*0.5)) | R38: 0 | S38: 0 | T38: 0 | U38: =IFERROR(T38/S38, 1) | V38: 0 | W38: =5*((O38*0.3)+(Q38*0.175)+(R38*0.175)+(U38*0.175)+((1-V38)*0.175))
A39: 46041 | B39: 11 | C39: Becca | D39: Ms. Bumbleflower | E39: 2 | F39: 1 | G39: 1 | H39: 4 | I39: 1 | J39: =F39-(1/H39) | K39: =((I39-((H39-1)/H39))-(-5/6))/((5-(5/6))-(-5/6)) | L39: =E39-((E40+E41+E42)/3) | M39: =0.5 + (L39 * 0.09) | N39: =((H39-(G39-1))/H39)*(IF(I39<>0,(I39+H39)/H39,1)) | O39: =(N39-(1/6))/(10/6) | P39: 11 | Q39: =IF(F39=1,(((1-((P39-3)/12))*0.5)+0.5),((P39/15)*0.5)) | R39: 1 | S39: 0 | T39: 0 | U39: =IFERROR(T39/S39, 1) | V39: 0 | W39: =5*((O39*0.3)+(Q39*0.175)+(R39*0.175)+(U39*0.175)+((1-V39)*0.175))
A40: 46041 | B40: 11 | C40: Ryan | D40: Davros, Dalek Creator | E40: 2 | F40: 0 | G40: 2 | H40: 4 | I40: 1 | J40: =F40-(1/H40) | K40: =((I40-((H40-1)/H40))-(-5/6))/((5-(5/6))-(-5/6)) | L40: =E40-((E39+E41+E42)/3) | M40: =0.5 + (L40 * 0.09) | N40: =((H40-(G40-1))/H40)*(IF(I40<>0,(I40+H40)/H40,1)) | O40: =(N40-(1/6))/(10/6) | P40: 11 | Q40: =IF(F40=1,(((1-((P40-3)/12))*0.5)+0.5),((P40/15)*0.5)) | R40: 1 | S40: 1 | T40: 1 | U40: =IFERROR(T40/S40, 1) | V40: 0 | W40: =5*((O40*0.3)+(Q40*0.175)+(R40*0.175)+(U40*0.175)+((1-V40)*0.175))
...

Sheet Game Log Season 2
A1: Base Game Info | F1: Player Score | P1: Turn of Victory/Loss | R1: Pop-Off | S1: Deck Resilience | V1: Games Clearly Behind | W1: Game Calculated Deck Strength
A2: Game Date | B2: Game # | C2: Player Name | D2: Commander | E2: Commander Strength | F2: Game Result | G2: Place | H2: Pod Size | I2: Knockouts | J2: Adjusted Pod Size Win/Loss Score | K2: Knockout Score | L2: Deck Strength Comparison Differential | M2: Win Probability based on Deck Strength | N2: Player Score | O2: Normalized Player Score | P2: TOV | Q2: Normalized TOV | R2: Pop-Off | S2: Disruptions | T2: Successful Recoveries | U2: Deck Resilience Score | V2: Games Clearly Behind | W2: Current Deck Bracket | X2: Game Calculated Deck Strength
A3: 46114 | B3: 1 | C3: Becca | D3: Ms. Bumbleflower | E3: 2 | F3: 1 | G3: 1 | H3: 5 | I3: 1 | J3: =F3-(1/H3) | K3: =((I3-((H3-1)/H3))-(-5/6))/((5-(5/6))-(-5/6)) | L3: =E3-((E4+E5+E6+E7)/4) | M3: =0.5 + (L3 * 0.09) | N3: =((H3-(G3-1))/H3)*(IF(I3<>0,(I3+H3)/H3,1)) | O3: =(N3-(1/6))/(10/6) | P3: 12 | Q3: =IF(F3=1,(((1-((P3-3)/15))*0.5)+0.5),((P3/18)*0.5)) | R3: 0 | S3: 0 | T3: 0 | U3: =IFERROR(T3/S3, 1) | V3: 0 | W3: 2 | X3: =((O3*0.3)+(Q3*0.175)+(R3*0.175)+(U3*0.175)+((1-V3)*0.175))+W3
A4: 46114 | B4: 1 | C4: Mateo | D4: High Perfect Morcant | E4: 2 | F4: 0 | G4: 2 | H4: 5 | I4: 1 | J4: =F4-(1/H4) | K4: =((I4-((H4-1)/H4))-(-5/6))/((5-(5/6))-(-5/6)) | L4: =E4-((E3+E5+E6+E7)/4) | M4: =0.5 + (L4 * 0.09) | N4: =((H4-(G4-1))/H4)*(IF(I4<>0,(I4+H4)/H4,1)) | O4: =(N4-(1/6))/(10/6) | P4: 12 | Q4: =IF(F4=1,(((1-((P4-3)/15))*0.5)+0.5),((P4/18)*0.5)) | R4: 0 | S4: 2 | T4: 0 | U4: =IFERROR(T4/S4, 1) | V4: 0 | W4: 2 | X4: =((O4*0.3)+(Q4*0.175)+(R4*0.175)+(U4*0.175)+((1-V4)*0.175))+W4
A5: 46114 | B5: 1 | C5: Manny | D5: Galadriel, Light of Valinor | E5: 3 | F5: 0 | G5: 3 | H5: 5 | I5: 1 | J5: =F5-(1/H5) | K5: =((I5-((H5-1)/H5))-(-5/6))/((5-(5/6))-(-5/6)) | L5: =E5-((E3+E4+E6+E7)/4) | M5: =0.5 + (L5 * 0.09) | N5: =((H5-(G5-1))/H5)*(IF(I5<>0,(I5+H5)/H5,1)) | O5: =(N5-(1/6))/(10/6) | P5: 11 | Q5: =IF(F5=1,(((1-((P5-3)/15))*0.5)+0.5),((P5/18)*0.5)) | R5: 1 | S5: 0 | T5: 0 | U5: =IFERROR(T5/S5, 1) | V5: 0 | W5: 3 | X5: =((O5*0.3)+(Q5*0.175)+(R5*0.175)+(U5*0.175)+((1-V5)*0.175))+W5
A6: 46114 | B6: 1 | C6: Ryan | D6: Eowyn, Shieldmaiden | E6: 3 | F6: 0 | G6: 4 | H6: 5 | I6: 1 | J6: =F6-(1/H6) | K6: =((I6-((H6-1)/H6))-(-5/6))/((5-(5/6))-(-5/6)) | L6: =E6-((E3+E4+E5+E7)/4) | M6: =0.5 + (L6 * 0.09) | N6: =((H6-(G6-1))/H6)*(IF(I6<>0,(I6+H6)/H6,1)) | O6: =(N6-(1/6))/(10/6) | P6: 9 | Q6: =IF(F6=1,(((1-((P6-3)/15))*0.5)+0.5),((P6/18)*0.5)) | R6: 1 | S6: 1 | T6: 1 | U6: =IFERROR(T6/S6, 1) | V6: 0 | W6: 3 | X6: =((O6*0.3)+(Q6*0.175)+(R6*0.175)+(U6*0.175)+((1-V6)*0.175))+W6
A7: 46114 | B7: 1 | C7: Kristy | D7: Edgar Markov | E7: 3 | F7: 0 | G7: 5 | H7: 5 | I7: 0 | J7: =F7-(1/H7) | K7: =((I7-((H7-1)/H7))-(-5/6))/((5-(5/6))-(-5/6)) | L7: =E7-((E3+E4+E5+E6)/4) | M7: =0.5 + (L7 * 0.09) | N7: =((H7-(G7-1))/H7)*(IF(I7<>0,(I7+H7)/H7,1)) | O7: =(N7-(1/6))/(10/6) | P7: 7 | Q7: =IF(F7=1,(((1-((P7-3)/15))*0.5)+0.5),((P7/18)*0.5)) | R7: 1 | S7: 0 | T7: 0 | U7: =IFERROR(T7/S7, 1) | V7: 0 | W7: 4 | X7: =((O7*0.3)+(Q7*0.175)+(R7*0.175)+(U7*0.175)+((1-V7)*0.175))+W7
A8: 46115 | B8: 2 | C8: Ryan | D8: Ashling, The Limitless | E8: 3 | F8: 1 | G8: 1 | H8: 6 | I8: 1 | J8: =F8-(1/H8) | K8: =((I8-((H8-1)/H8))-(-5/6))/((5-(5/6))-(-5/6)) | L8: =E8-((E9+E10+E11+E12+E13)/5) | M8: =0.5 + (L8 * 0.09) | N8: =((H8-(G8-1))/H8)*(IF(I8<>0,(I8+H8)/H8,1)) | O8: =(N8-(1/6))/(10/6) | P8: 13 | Q8: =IF(F8=1,(((1-((P8-3)/15))*0.5)+0.5),((P8/18)*0.5)) | R8: 1 | S8: 1 | T8: 0 | U8: =IFERROR(T8/S8, 1) | V8: 0 | W8: 3 | X8: =((O8*0.3)+(Q8*0.175)+(R8*0.175)+(U8*0.175)+((1-V8)*0.175))+W8
A9: 46115 | B9: 2 | C9: Mateo | D9: Leonardo, the Balance/Michelangelo, the Heart | E9: 2 | F9: 0 | G9: 2 | H9: 6 | I9: 4 | J9: =F9-(1/H9) | K9: =((I9-((H9-1)/H9))-(-5/6))/((5-(5/6))-(-5/6)) | L9: =E9-((E8+E10+E11+E12+E13)/5) | M9: =0.5 + (L9 * 0.09) | N9: =((H9-(G9-1))/H9)*(IF(I9<>0,(I9+H9)/H9,1)) | O9: =(N9-(1/6))/(10/6) | P9: 13 | Q9: =IF(F9=1,(((1-((P9-3)/15))*0.5)+0.5),((P9/18)*0.5)) | R9: 1 | S9: 1 | T9: 0 | U9: =IFERROR(T9/S9, 1) | V9: 0 | W9: 2 | X9: =((O9*0.3)+(Q9*0.175)+(R9*0.175)+(U9*0.175)+((1-V9)*0.175))+W9
A10: 46115 | B10: 2 | C10: Joseph | D10: Valgavoth, Harrower of Souls | E10: 3 | F10: 0 | G10: 3 | H10: 6 | I10: 0 | J10: =F10-(1/H10) | K10: =((I10-((H10-1)/H10))-(-5/6))/((5-(5/6))-(-5/6)) | L10: =E10-((E8+E9+E11+E12+E13)/5) | M10: =0.5 + (L10 * 0.09) | N10: =((H10-(G10-1))/H10)*(IF(I10<>0,(I10+H10)/H10,1)) | O10: =(N10-(1/6))/(10/6) | P10: 12 | Q10: =IF(F10=1,(((1-((P10-3)/15))*0.5)+0.5),((P10/18)*0.5)) | R10: 0 | S10: 2 | T10: 1 | U10: =IFERROR(T10/S10, 1) | V10: 1 | W10: 3 | X10: =((O10*0.3)+(Q10*0.175)+(R10*0.175)+(U10*0.175)+((1-V10)*0.175))+W10
A11: 46115 | B11: 2 | C11: Red | D11: Cloud, Ex-SOLDIER | E11: 2 | F11: 0 | G11: 3 | H11: 6 | I11: 0 | J11: =F11-(1/H11) | K11: =((I11-((H11-1)/H11))-(-5/6))/((5-(5/6))-(-5/6)) | L11: =E11-((E8+E9+E10+E12+E13)/5) | M11: =0.5 + (L11 * 0.09) | N11: =((H11-(G11-1))/H11)*(IF(I11<>0,(I11+H11)/H11,1)) | O11: =(N11-(1/6))/(10/6) | P11: 12 | Q11: =IF(F11=1,(((1-((P11-3)/15))*0.5)+0.5),((P11/18)*0.5)) | R11: 0 | S11: 0 | T11: 0 | U11: =IFERROR(T11/S11, 1) | V11: 1 | W11: 2 | X11: =((O11*0.3)+(Q11*0.175)+(R11*0.175)+(U11*0.175)+((1-V11)*0.175))+W11
A12: 46115 | B12: 2 | C12: Kristy | D12: Edgar Markov | E12: 3 | F12: 0 | G12: 5 | H12: 6 | I12: 0 | J12: =F12-(1/H12) | K12: =((I12-((H12-1)/H12))-(-5/6))/((5-(5/6))-(-5/6)) | L12: =E12-((E8+E9+E10+E11+E13)/5) | M12: =0.5 + (L12 * 0.09) | N12: =((H12-(G12-1))/H12)*(IF(I12<>0,(I12+H12)/H12,1)) | O12: =(N12-(1/6))/(10/6) | P12: 11 | Q12: =IF(F12=1,(((1-((P12-3)/15))*0.5)+0.5),((P12/18)*0.5)) | R12: 1 | S12: 0 | T12: 0 | U12: =IFERROR(T12/S12, 1) | V12: 0 | W12: 4 | X12: =((O12*0.3)+(Q12*0.175)+(R12*0.175)+(U12*0.175)+((1-V12)*0.175))+W12
A13: 46115 | B13: 2 | C13: Manny | D13: Atraxa, Praetor's Voice | E13: 3 | F13: 0 | G13: 6 | H13: 6 | I13: 0 | J13: =F13-(1/H13) | K13: =((I13-((H13-1)/H13))-(-5/6))/((5-(5/6))-(-5/6)) | L13: =E13-((E8+E9+E10+E11+E12)/5) | M13: =0.5 + (L13 * 0.09) | N13: =((H13-(G13-1))/H13)*(IF(I13<>0,(I13+H13)/H13,1)) | O13: =(N13-(1/6))/(10/6) | P13: 11 | Q13: =IF(F13=1,(((1-((P13-3)/15))*0.5)+0.5),((P13/18)*0.5)) | R13: 1 | S13: 0 | T13: 0 | U13: =IFERROR(T13/S13, 1) | V13: 0 | W13: 3 | X13: =((O13*0.3)+(Q13*0.175)+(R13*0.175)+(U13*0.175)+((1-V13)*0.175))+W13
A14: 46122 | B14: 3 | C14: Mateo | D14: Zurgo Stormrender | E14: 3 | F14: 1 | G14: 1 | H14: 3 | I14: 2 | J14: =F14-(1/H14) | K14: =((I14-((H14-1)/H14))-(-5/6))/((5-(5/6))-(-5/6)) | L14: =E14-((E15+E16)/2) | M14: =0.5 + (L14 * 0.09) | N14: =((H14-(G14-1))/H14)*(IF(I14<>0,(I14+H14)/H14,1)) | O14: =(N14-(1/6))/(10/6) | P14: 9 | Q14: =IF(F14=1,(((1-((P14-3)/15))*0.5)+0.5),((P14/18)*0.5)) | R14: 1 | S14: 1 | T14: 1 | U14: =IFERROR(T14/S14, 1) | V14: 0 | W14: 3 | X14: =((O14*0.3)+(Q14*0.175)+(R14*0.175)+(U14*0.175)+((1-V14)*0.175))+W14
A15: 46122 | B15: 3 | C15: Becca | D15: Aminatou, Veil Piercer | E15: 3 | F15: 0 | G15: 2 | H15: 3 | I15: 0 | J15: =F15-(1/H15) | K15: =((I15-((H15-1)/H15))-(-5/6))/((5-(5/6))-(-5/6)) | L15: =E15-((E14+E16)/2) | M15: =0.5 + (L15 * 0.09) | N15: =((H15-(G15-1))/H15)*(IF(I15<>0,(I15+H15)/H15,1)) | O15: =(N15-(1/6))/(10/6) | P15: 9 | Q15: =IF(F15=1,(((1-((P15-3)/15))*0.5)+0.5),((P15/18)*0.5)) | R15: 1 | S15: 0 | T15: 0 | U15: =IFERROR(T15/S15, 1) | V15: 0 | W15: 4 | X15: =((O15*0.3)+(Q15*0.175)+(R15*0.175)+(U15*0.175)+((1-V15)*0.175))+W15
A16: 46122 | B16: 3 | C16: Ryan | D16: Kratos, Stoic Father/Atreus, Impulsive Son | E16: 2 | F16: 0 | G16: 3 | H16: 3 | I16: 0 | J16: =F16-(1/H16) | K16: =((I16-((H16-1)/H16))-(-5/6))/((5-(5/6))-(-5/6)) | L16: =E16-((E14+E15)/2) | M16: =0.5 + (L16 * 0.09) | N16: =((H16-(G16-1))/H16)*(IF(I16<>0,(I16+H16)/H16,1)) | O16: =(N16-(1/6))/(10/6) | P16: 8 | Q16: =IF(F16=1,(((1-((P16-3)/15))*0.5)+0.5),((P16/18)*0.5)) | R16: 1 | S16: 0 | T16: 0 | U16: =IFERROR(T16/S16, 1) | V16: 0 | W16: 2 | X16: =((O16*0.3)+(Q16*0.175)+(R16*0.175)+(U16*0.175)+((1-V16)*0.175))+W16
A17: 46122 | B17: 4 | C17: Ryan | D17: Cloud, Ex-SOLDIER | E17: 3 | F17: 1 | G17: 1 | H17: 3 | I17: 2 | J17: =F17-(1/H17) | K17: =((I17-((H17-1)/H17))-(-5/6))/((5-(5/6))-(-5/6)) | L17: =E17-((E18+E19)/2) | M17: =0.5 + (L17 * 0.09) | N17: =((H17-(G17-1))/H17)*(IF(I17<>0,(I17+H17)/H17,1)) | O17: =(N17-(1/6))/(10/6) | P17: 12 | Q17: =IF(F17=1,(((1-((P17-3)/15))*0.5)+0.5),((P17/18)*0.5)) | R17: 1 | S17: 0 | T17: 0 | U17: =IFERROR(T17/S17, 1) | V17: 0 | W17: 3 | X17: =((O17*0.3)+(Q17*0.175)+(R17*0.175)+(U17*0.175)+((1-V17)*0.175))+W17
A18: 46122 | B18: 4 | C18: Becca | D18: Ms. Bumbleflower | E18: 2.6 | F18: 0 | G18: 2 | H18: 3 | I18: 0 | J18: =F18-(1/H18) | K18: =((I18-((H18-1)/H18))-(-5/6))/((5-(5/6))-(-5/6)) | L18: =E18-((E17+E19)/2) | M18: =0.5 + (L18 * 0.09) | N18: =((H18-(G18-1))/H18)*(IF(I18<>0,(I18+H18)/H18,1)) | O18: =(N18-(1/6))/(10/6) | P18: 12 | Q18: =IF(F18=1,(((1-((P18-3)/15))*0.5)+0.5),((P18/18)*0.5)) | R18: 0 | S18: 1 | T18: 0 | U18: =IFERROR(T18/S18, 1) | V18: 0 | W18: 2 | X18: =((O18*0.3)+(Q18*0.175)+(R18*0.175)+(U18*0.175)+((1-V18)*0.175))+W18
A19: 46122 | B19: 4 | C19: Mateo | D19: Fire Lord Azula | E19: 2 | F19: 0 | G19: 3 | H19: 3 | I19: 0 | J19: =F19-(1/H19) | K19: =((I19-((H19-1)/H19))-(-5/6))/((5-(5/6))-(-5/6)) | L19: =E19-((E17+E18)/2) | M19: =0.5 + (L19 * 0.09) | N19: =((H19-(G19-1))/H19)*(IF(I19<>0,(I19+H19)/H19,1)) | O19: =(N19-(1/6))/(10/6) | P19: 8 | Q19: =IF(F19=1,(((1-((P19-3)/15))*0.5)+0.5),((P19/18)*0.5)) | R19: 1 | S19: 1 | T19: 0 | U19: =IFERROR(T19/S19, 1) | V19: 0 | W19: 3 | X19: =((O19*0.3)+(Q19*0.175)+(R19*0.175)+(U19*0.175)+((1-V19)*0.175))+W19
A20: 46129 | B20: 5 | C20: Mateo | D20: Quintorius, History Chaser | E20: 2 | F20: 1 | G20: 1 | H20: 6 | I20: 4 | J20: =F20-(1/H20) | K20: =((I20-((H20-1)/H20))-(-5/6))/((5-(5/6))-(-5/6)) | L20: =E20-((E21+E22+E23+E24+E25)/5) | M20: =0.5 + (L20 * 0.09) | N20: =((H20-(G20-1))/H20)*(IF(I20<>0,(I20+H20)/H20,1)) | O20: =(N20-(1/6))/(10/6) | P20: 8 | Q20: =IF(F20=1,(((1-((P20-3)/15))*0.5)+0.5),((P20/18)*0.5)) | R20: 1 | S20: 0 | T20: 0 | U20: =IFERROR(T20/S20, 1) | V20: 0 | W20: 2 | X20: =((O20*0.3)+(Q20*0.175)+(R20*0.175)+(U20*0.175)+((1-V20)*0.175))+W20
A21: 46129 | B21: 5 | C21: Becca | D21: Killian, Decisive Mentor | E21: 2 | F21: 0 | G21: 2 | H21: 6 | I21: 0 | J21: =F21-(1/H21) | K21: =((I21-((H21-1)/H21))-(-5/6))/((5-(5/6))-(-5/6)) | L21: =E21-((E20+E22+E23+E24+E25)/5) | M21: =0.5 + (L21 * 0.09) | N21: =((H21-(G21-1))/H21)*(IF(I21<>0,(I21+H21)/H21,1)) | O21: =(N21-(1/6))/(10/6) | P21: 8 | Q21: =IF(F21=1,(((1-((P21-3)/15))*0.5)+0.5),((P21/18)*0.5)) | R21: 1 | S21: 1 | T21: 0 | U21: =IFERROR(T21/S21, 1) | V21: 0 | W21: 2 | X21: =((O21*0.3)+(Q21*0.175)+(R21*0.175)+(U21*0.175)+((1-V21)*0.175))+W21
A22: 46129 | B22: 5 | C22: Kristy | D22: Auntie Ool, Cursewretch | E22: 3 | F22: 0 | G22: 2 | H22: 6 | I22: 0 | J22: =F22-(1/H22) | K22: =((I22-((H22-1)/H22))-(-5/6))/((5-(5/6))-(-5/6)) | L22: =E22-((E20+E21+E23+E24+E25)/5) | M22: =0.5 + (L22 * 0.09) | N22: =((H22-(G22-1))/H22)*(IF(I22<>0,(I22+H22)/H22,1)) | O22: =(N22-(1/6))/(10/6) | P22: 8 | Q22: =IF(F22=1,(((1-((P22-3)/15))*0.5)+0.5),((P22/18)*0.5)) | R22: 0 | S22: 1 | T22: 0 | U22: =IFERROR(T22/S22, 1) | V22: 0 | W22: 4 | X22: =((O22*0.3)+(Q22*0.175)+(R22*0.175)+(U22*0.175)+((1-V22)*0.175))+W22
A23: 46129 | B23: 5 | C23: Joseph | D23: Zimone, Infinite Analyst | E23: 2 | F23: 0 | G23: 2 | H23: 6 | I23: 0 | J23: =F23-(1/H23) | K23: =((I23-((H23-1)/H23))-(-5/6))/((5-(5/6))-(-5/6)) | L23: =E23-((E20+E21+E22+E24+E25)/5) | M23: =0.5 + (L23 * 0.09) | N23: =((H23-(G23-1))/H23)*(IF(I23<>0,(I23+H23)/H23,1)) | O23: =(N23-(1/6))/(10/6) | P23: 8 | Q23: =IF(F23=1,(((1-((P23-3)/15))*0.5)+0.5),((P23/18)*0.5)) | R23: 0 | S23: 1 | T23: 0 | U23: =IFERROR(T23/S23, 1) | V23: 1 | W23: 2 | X23: =((O23*0.3)+(Q23*0.175)+(R23*0.175)+(U23*0.175)+((1-V23)*0.175))+W23
A24: 46129 | B24: 5 | C24: Ryan | D24: Ashling, The Limitless | E24: 3.6 | F24: 0 | G24: 5 | H24: 6 | I24: 0 | J24: =F24-(1/H24) | K24: =((I24-((H24-1)/H24))-(-5/6))/((5-(5/6))-(-5/6)) | L24: =E24-((E20+E21+E22+E23+E25)/5) | M24: =0.5 + (L24 * 0.09) | N24: =((H24-(G24-1))/H24)*(IF(I24<>0,(I24+H24)/H24,1)) | O24: =(N24-(1/6))/(10/6) | P24: 7 | Q24: =IF(F24=1,(((1-((P24-3)/15))*0.5)+0.5),((P24/18)*0.5)) | R24: 1 | S24: 1 | T24: 0 | U24: =IFERROR(T24/S24, 1) | V24: 0 | W24: 3 | X24: =((O24*0.3)+(Q24*0.175)+(R24*0.175)+(U24*0.175)+((1-V24)*0.175))+W24
A25: 46129 | B25: 5 | C25: Michelle | D25: The Wise Mothman | E25: 2 | F25: 0 | G25: 6 | H25: 6 | I25: 0 | J25: =F25-(1/H25) | K25: =((I25-((H25-1)/H25))-(-5/6))/((5-(5/6))-(-5/6)) | L25: =E25-((E20+E21+E22+E23+E24)/5) | M25: =0.5 + (L25 * 0.09) | N25: =((H25-(G25-1))/H25)*(IF(I25<>0,(I25+H25)/H25,1)) | O25: =(N25-(1/6))/(10/6) | P25: 5 | Q25: =IF(F25=1,(((1-((P25-3)/15))*0.5)+0.5),((P25/18)*0.5)) | R25: 0 | S25: 0 | T25: 0 | U25: =IFERROR(T25/S25, 1) | V25: 0 | W25: 2 | X25: =((O25*0.3)+(Q25*0.175)+(R25*0.175)+(U25*0.175)+((1-V25)*0.175))+W25
A26: 46129 | B26: 6 | C26: Mateo | D26: Auntie Ool, Cursewretch | E26: 3 | F26: 1 | G26: 1 | H26: 5 | I26: 3 | J26: =F26-(1/H26) | K26: =((I26-((H26-1)/H26))-(-5/6))/((5-(5/6))-(-5/6)) | L26: =E26-((E27+E28+E29+E30)/4) | M26: =0.5 + (L26 * 0.09) | N26: =((H26-(G26-1))/H26)*(IF(I26<>0,(I26+H26)/H26,1)) | O26: =(N26-(1/6))/(10/6) | P26: 11 | Q26: =IF(F26=1,(((1-((P26-3)/15))*0.5)+0.5),((P26/18)*0.5)) | R26: 1 | S26: 1 | T26: 1 | U26: =IFERROR(T26/S26, 1) | V26: 0 | W26: 4 | X26: =((O26*0.3)+(Q26*0.175)+(R26*0.175)+(U26*0.175)+((1-V26)*0.175))+W26
A27: 46129 | B27: 6 | C27: Ryan | D27: Fire Lord Zuko | E27: 3 | F27: 0 | G27: 2 | H27: 5 | I27: 0 | J27: =F27-(1/H27) | K27: =((I27-((H27-1)/H27))-(-5/6))/((5-(5/6))-(-5/6)) | L27: =E27-((E26+E28+E29+E30)/4) | M27: =0.5 + (L27 * 0.09) | N27: =((H27-(G27-1))/H27)*(IF(I27<>0,(I27+H27)/H27,1)) | O27: =(N27-(1/6))/(10/6) | P27: 11 | Q27: =IF(F27=1,(((1-((P27-3)/15))*0.5)+0.5),((P27/18)*0.5)) | R27: 0 | S27: 2 | T27: 1 | U27: =IFERROR(T27/S27, 1) | V27: 1 | W27: 3 | X27: =((O27*0.3)+(Q27*0.175)+(R27*0.175)+(U27*0.175)+((1-V27)*0.175))+W27
A28: 46129 | B28: 6 | C28: Becca | D28: Killian, Decisive Mentor | E28: 2.5 | F28: 0 | G28: 2 | H28: 5 | I28: 0 | J28: =F28-(1/H28) | K28: =((I28-((H28-1)/H28))-(-5/6))/((5-(5/6))-(-5/6)) | L28: =E28-((E26+E27+E29+E30)/4) | M28: =0.5 + (L28 * 0.09) | N28: =((H28-(G28-1))/H28)*(IF(I28<>0,(I28+H28)/H28,1)) | O28: =(N28-(1/6))/(10/6) | P28: 11 | Q28: =IF(F28=1,(((1-((P28-3)/15))*0.5)+0.5),((P28/18)*0.5)) | R28: 1 | S28: 1 | T28: 1 | U28: =IFERROR(T28/S28, 1) | V28: 0 | W28: 2 | X28: =((O28*0.3)+(Q28*0.175)+(R28*0.175)+(U28*0.175)+((1-V28)*0.175))+W28
A29: 46129 | B29: 6 | C29: Joseph | D29: Super Shredder | E29: 2 | F29: 0 | G29: 4 | H29: 5 | I29: 0 | J29: =F29-(1/H29) | K29: =((I29-((H29-1)/H29))-(-5/6))/((5-(5/6))-(-5/6)) | L29: =E29-((E26+E27+E28+E30)/4) | M29: =0.5 + (L29 * 0.09) | N29: =((H29-(G29-1))/H29)*(IF(I29<>0,(I29+H29)/H29,1)) | O29: =(N29-(1/6))/(10/6) | P29: 9 | Q29: =IF(F29=1,(((1-((P29-3)/15))*0.5)+0.5),((P29/18)*0.5)) | R29: 1 | S29: 1 | T29: 0 | U29: =IFERROR(T29/S29, 1) | V29: 0 | W29: 2 | X29: =((O29*0.3)+(Q29*0.175)+(R29*0.175)+(U29*0.175)+((1-V29)*0.175))+W29
A30: 46129 | B30: 6 | C30: Kristy | D30: Dina, Essence Brewer | E30: 2 | F30: 0 | G30: 5 | H30: 5 | I30: 0 | J30: =F30-(1/H30) | K30: =((I30-((H30-1)/H30))-(-5/6))/((5-(5/6))-(-5/6)) | L30: =E30-((E26+E27+E28+E29)/4) | M30: =0.5 + (L30 * 0.09) | N30: =((H30-(G30-1))/H30)*(IF(I30<>0,(I30+H30)/H30,1)) | O30: =(N30-(1/6))/(10/6) | P30: 9 | Q30: =IF(F30=1,(((1-((P30-3)/15))*0.5)+0.5),((P30/18)*0.5)) | R30: 0 | S30: 2 | T30: 0 | U30: =IFERROR(T30/S30, 1) | V30: 0 | W30: 2 | X30: =((O30*0.3)+(Q30*0.175)+(R30*0.175)+(U30*0.175)+((1-V30)*0.175))+W30
A31: 46134 | B31: 7 | C31: Manny | D31: Galadriel, Light of Valinor | E31: 3.7 | F31: 1 | G31: 1 | H31: 4 | I31: 3 | J31: =F31-(1/H31) | K31: =((I31-((H31-1)/H31))-(-5/6))/((5-(5/6))-(-5/6)) | L31: =E31-((E32+E33+E34)/3) | M31: =0.5 + (L31 * 0.09) | N31: =((H31-(G31-1))/H31)*(IF(I31<>0,(I31+H31)/H31,1)) | O31: =(N31-(1/6))/(10/6) | P31: 9 | Q31: =IF(F31=1,(((1-((P31-3)/15))*0.5)+0.5),((P31/18)*0.5)) | R31: 1 | S31: 0 | T31: 0 | U31: =IFERROR(T31/S31, 1) | V31: 0 | W31: 3 | X31: =((O31*0.3)+(Q31*0.175)+(R31*0.175)+(U31*0.175)+((1-V31)*0.175))+W31
A32: 46134 | B32: 7 | C32: Joseph | D32: Zimone, Infinite Analyst | E32: 2.2 | F32: 0 | G32: 2 | H32: 4 | I32: 0 | J32: =F32-(1/H32) | K32: =((I32-((H32-1)/H32))-(-5/6))/((5-(5/6))-(-5/6)) | L32: =E32-((E31+E33+E34)/3) | M32: =0.5 + (L32 * 0.09) | N32: =((H32-(G32-1))/H32)*(IF(I32<>0,(I32+H32)/H32,1)) | O32: =(N32-(1/6))/(10/6) | P32: 9 | Q32: =IF(F32=1,(((1-((P32-3)/15))*0.5)+0.5),((P32/18)*0.5)) | R32: 1 | S32: 0 | T32: 0 | U32: =IFERROR(T32/S32, 1) | V32: 0 | W32: 2 | X32: =((O32*0.3)+(Q32*0.175)+(R32*0.175)+(U32*0.175)+((1-V32)*0.175))+W32
A33: 46134 | B33: 7 | C33: Ryan | D33: Ashling, The Limitless | E33: 3.4 | F33: 0 | G33: 2 | H33: 4 | I33: 0 | J33: =F33-(1/H33) | K33: =((I33-((H33-1)/H33))-(-5/6))/((5-(5/6))-(-5/6)) | L33: =E33-((E31+E32+E34)/3) | M33: =0.5 + (L33 * 0.09) | N33: =((H33-(G33-1))/H33)*(IF(I33<>0,(I33+H33)/H33,1)) | O33: =(N33-(1/6))/(10/6) | P33: 9 | Q33: =IF(F33=1,(((1-((P33-3)/15))*0.5)+0.5),((P33/18)*0.5)) | R33: 1 | S33: 3 | T33: 2 | U33: =IFERROR(T33/S33, 1) | V33: 0 | W33: 3 | X33: =((O33*0.3)+(Q33*0.175)+(R33*0.175)+(U33*0.175)+((1-V33)*0.175))+W33
A34: 46134 | B34: 7 | C34: Kristy | D34: Dina, Essence Brewer | E34: 2.2 | F34: 0 | G34: 4 | H34: 4 | I34: 0 | J34: =F34-(1/H34) | K34: =((I34-((H34-1)/H34))-(-5/6))/((5-(5/6))-(-5/6)) | L34: =E34-((E31+E32+E33)/3) | M34: =0.5 + (L34 * 0.09) | N34: =((H34-(G34-1))/H34)*(IF(I34<>0,(I34+H34)/H34,1)) | O34: =(N34-(1/6))/(10/6) | P34: 8 | Q34: =IF(F34=1,(((1-((P34-3)/15))*0.5)+0.5),((P34/18)*0.5)) | R34: 0 | S34: 1 | T34: 0 | U34: =IFERROR(T34/S34, 1) | V34: 0 | W34: 2 | X34: =((O34*0.3)+(Q34*0.175)+(R34*0.175)+(U34*0.175)+((1-V34)*0.175))+W34
A35: 46143 | B35: 8 | C35: Ryan | D35: Witherbloom, The Balancer | E35: 2 | F35: 1 | G35: 1 | H35: 6 | I35: 3 | J35: =F35-(1/H35) | K35: =((I35-((H35-1)/H35))-(-5/6))/((5-(5/6))-(-5/6)) | L35: =E35-((E36+E37+E38+E39+E40)/5) | M35: =0.5 + (L35 * 0.09) | N35: =((H35-(G35-1))/H35)*(IF(I35<>0,(I35+H35)/H35,1)) | O35: =(N35-(1/6))/(10/6) | P35: 14 | Q35: =IF(F35=1,(((1-((P35-3)/15))*0.5)+0.5),((P35/18)*0.5)) | R35: 1 | S35: 1 | T35: 0 | U35: =IFERROR(T35/S35, 1) | V35: 0 | W35: 2 | X35: =((O35*0.3)+(Q35*0.175)+(R35*0.175)+(U35*0.175)+((1-V35)*0.175))+W35
A36: 46143 | B36: 8 | C36: Mateo | D36: Killian, Decisive Mentor (Becca's) | E36: 2 | F36: 0 | G36: 2 | H36: 6 | I36: 1 | J36: =F36-(1/H36) | K36: =((I36-((H36-1)/H36))-(-5/6))/((5-(5/6))-(-5/6)) | L36: =E36-((E35+E37+E38+E39+E40)/5) | M36: =0.5 + (L36 * 0.09) | N36: =((H36-(G36-1))/H36)*(IF(I36<>0,(I36+H36)/H36,1)) | O36: =(N36-(1/6))/(10/6) | P36: 14 | Q36: =IF(F36=1,(((1-((P36-3)/15))*0.5)+0.5),((P36/18)*0.5)) | R36: 1 | S36: 0 | T36: 0 | U36: =IFERROR(T36/S36, 1) | V36: 0 | W36: 2 | X36: =((O36*0.3)+(Q36*0.175)+(R36*0.175)+(U36*0.175)+((1-V36)*0.175))+W36
A37: 46143 | B37: 8 | C37: Joseph | D37: Super Shredder | E37: 2.4 | F37: 0 | G37: 3 | H37: 6 | I37: 1 | J37: =F37-(1/H37) | K37: =((I37-((H37-1)/H37))-(-5/6))/((5-(5/6))-(-5/6)) | L37: =E37-((E35+E36+E38+E39+E40)/5) | M37: =0.5 + (L37 * 0.09) | N37: =((H37-(G37-1))/H37)*(IF(I37<>0,(I37+H37)/H37,1)) | O37: =(N37-(1/6))/(10/6) | P37: 14 | Q37: =IF(F37=1,(((1-((P37-3)/15))*0.5)+0.5),((P37/18)*0.5)) | R37: 1 | S37: 0 | T37: 0 | U37: =IFERROR(T37/S37, 1) | V37: 0 | W37: 2 | X37: =((O37*0.3)+(Q37*0.175)+(R37*0.175)+(U37*0.175)+((1-V37)*0.175))+W37
A38: 46143 | B38: 8 | C38: Manny | D38: Athreos, God of Passage | E38: 3 | F38: 0 | G38: 4 | H38: 6 | I38: 0 | J38: =F38-(1/H38) | K38: =((I38-((H38-1)/H38))-(-5/6))/((5-(5/6))-(-5/6)) | L38: =E38-((E35+E36+E37+E39+E40)/5) | M38: =0.5 + (L38 * 0.09) | N38: =((H38-(G38-1))/H38)*(IF(I38<>0,(I38+H38)/H38,1)) | O38: =(N38-(1/6))/(10/6) | P38: 11 | Q38: =IF(F38=1,(((1-((P38-3)/15))*0.5)+0.5),((P38/18)*0.5)) | R38: 0 | S38: 0 | T38: 0 | U38: =IFERROR(T38/S38, 1) | V38: 1 | W38: 3 | X38: =((O38*0.3)+(Q38*0.175)+(R38*0.175)+(U38*0.175)+((1-V38)*0.175))+W38
A39: 46143 | B39: 8 | C39: Kristy | D39: Dina, Essence Brewer | E39: 2.2 | F39: 0 | G39: 5 | H39: 6 | I39: 0 | J39: =F39-(1/H39) | K39: =((I39-((H39-1)/H39))-(-5/6))/((5-(5/6))-(-5/6)) | L39: =E39-((E35+E36+E37+E38+E40)/5) | M39: =0.5 + (L39 * 0.09) | N39: =((H39-(G39-1))/H39)*(IF(I39<>0,(I39+H39)/H39,1)) | O39: =(N39-(1/6))/(10/6) | P39: 9 | Q39: =IF(F39=1,(((1-((P39-3)/15))*0.5)+0.5),((P39/18)*0.5)) | R39: 0 | S39: 1 | T39: 0 | U39: =IFERROR(T39/S39, 1) | V39: 0 | W39: 2 | X39: =((O39*0.3)+(Q39*0.175)+(R39*0.175)+(U39*0.175)+((1-V39)*0.175))+W39
A40: 46143 | B40: 8 | C40: Red | D40: Squall, SeeD Mercenary | E40: 3 | F40: 0 | G40: 6 | H40: 6 | I40: 0 | J40: =F40-(1/H40) | K40: =((I40-((H40-1)/H40))-(-5/6))/((5-(5/6))-(-5/6)) | L40: =E40-((E35+E36+E37+E38+E39)/5) | M40: =0.5 + (L40 * 0.09) | N40: =((H40-(G40-1))/H40)*(IF(I40<>0,(I40+H40)/H40,1)) | O40: =(N40-(1/6))/(10/6) | P40: 9 | Q40: =IF(F40=1,(((1-((P40-3)/15))*0.5)+0.5),((P40/18)*0.5)) | R40: 1 | S40: 1 | T40: 1 | U40: =IFERROR(T40/S40, 1) | V40: 0 | W40: 3 | X40: =((O40*0.3)+(Q40*0.175)+(R40*0.175)+(U40*0.175)+((1-V40)*0.175))+W40
...

Sheet Game Log Season 3
A1: Base Game Info | F1: Player Score | P1: Turn of Victory/Loss | R1: Pop-Off | S1: Deck Resilience | V1: Games Clearly Behind | W1: Game Calculated Deck Strength | Y1: Playgroup Game ID
A2: Game Date | B2: Game # | C2: Player Name | D2: Commander | E2: Commander Strength | F2: Game Result | G2: Place | H2: Pod Size | I2: Knockouts | J2: Adjusted Pod Size Win/Loss Score | K2: Knockout Score | L2: Deck Strength Comparison Differential | M2: Win Probability based on Deck Strength | N2: Player Score | O2: Normalized Player Score | P2: TOV | Q2: Normalized TOV | R2: Pop-Off | S2: Disruptions | T2: Successful Recoveries | U2: Deck Resilience Score | V2: Games Clearly Behind | W2: Current Deck Bracket | X2: Game Calculated Deck Strength | Y2: Playgroup Game ID
A3: 46204 | B3: 1 | C3: Becca | D3: Ms. Bumbleflower | E3: 2.9 | F3: 0 | G3: 2 | H3: 5 | I3: 0 | J3: =F3-(1/H3) | K3: =((I3-((H3-1)/H3))-(-5/6))/((5-(5/6))-(-5/6)) | L3: =E3-((E4+E5+E6+E7)/4) | M3: =0.5 + (L3 * 0.09) | N3: =((H3-(G3-1))/H3)*(IF(I3<>0,(I3+H3)/H3,1)) | O3: =(N3-(1/6))/(10/6) | P3: 10 | Q3: =IF(F3=1,(((1-((P3-3)/15))*0.5)+0.5),((P3/18)*0.5)) | R3: 0 | S3: 1 | T3: 1 | U3: =IFERROR(T3/S3, 1) | V3: 0 | W3: 2 | X3: =((O3*0.3)+(Q3*0.175)+(R3*0.175)+(U3*0.175)+((1-V3)*0.175))+W3 | Y3: 767378
A4: 46204 | B4: 1 | C4: Mateo | D4: Captain America, Team Leader | E4: 3.7 | F4: 0 | G4: 2 | H4: 5 | I4: 0 | J4: =F4-(1/H4) | K4: =((I4-((H4-1)/H4))-(-5/6))/((5-(5/6))-(-5/6)) | L4: =E4-((E3+E5+E6+E7)/4) | M4: =0.5 + (L4 * 0.09) | N4: =((H4-(G4-1))/H4)*(IF(I4<>0,(I4+H4)/H4,1)) | O4: =(N4-(1/6))/(10/6) | P4: 10 | Q4: =IF(F4=1,(((1-((P4-3)/15))*0.5)+0.5),((P4/18)*0.5)) | R4: 1 | S4: 1 | T4: 1 | U4: =IFERROR(T4/S4, 1) | V4: 0 | W4: 3 | X4: =((O4*0.3)+(Q4*0.175)+(R4*0.175)+(U4*0.175)+((1-V4)*0.175))+W4 | Y4: 767378
A5: 46204 | B5: 1 | C5: Manny | D5: Kruphix, God of Horizons | E5: 2 | F5: 0 | G5: 2 | H5: 5 | I5: 0 | J5: =F5-(1/H5) | K5: =((I5-((H5-1)/H5))-(-5/6))/((5-(5/6))-(-5/6)) | L5: =E5-((E3+E4+E6+E7)/4) | M5: =0.5 + (L5 * 0.09) | N5: =((H5-(G5-1))/H5)*(IF(I5<>0,(I5+H5)/H5,1)) | O5: =(N5-(1/6))/(10/6) | P5: 10 | Q5: =IF(F5=1,(((1-((P5-3)/15))*0.5)+0.5),((P5/18)*0.5)) | R5: 1 | S5: 0 | T5: 0 | U5: =IFERROR(T5/S5, 1) | V5: 0 | W5: 2 | X5: =((O5*0.3)+(Q5*0.175)+(R5*0.175)+(U5*0.175)+((1-V5)*0.175))+W5 | Y5: 767378
A6: 46204 | B6: 1 | C6: Ryan | D6: Fire Lord Zuko | E6: 3.9 | F6: 1 | G6: 1 | H6: 5 | I6: 4 | J6: =F6-(1/H6) | K6: =((I6-((H6-1)/H6))-(-5/6))/((5-(5/6))-(-5/6)) | L6: =E6-((E3+E4+E5+E7)/4) | M6: =0.5 + (L6 * 0.09) | N6: =((H6-(G6-1))/H6)*(IF(I6<>0,(I6+H6)/H6,1)) | O6: =(N6-(1/6))/(10/6) | P6: 10 | Q6: =IF(F6=1,(((1-((P6-3)/15))*0.5)+0.5),((P6/18)*0.5)) | R6: 1 | S6: 1 | T6: 0 | U6: =IFERROR(T6/S6, 1) | V6: 0 | W6: 3 | X6: =((O6*0.3)+(Q6*0.175)+(R6*0.175)+(U6*0.175)+((1-V6)*0.175))+W6 | Y6: 767378
A7: 46204 | B7: 1 | C7: Kristy | D7: Auntie Ool, Cursewretch | E7: 3.4 | F7: 0 | G7: 2 | H7: 5 | I7: 0 | J7: =F7-(1/H7) | K7: =((I7-((H7-1)/H7))-(-5/6))/((5-(5/6))-(-5/6)) | L7: =E7-((E3+E4+E5+E6)/4) | M7: =0.5 + (L7 * 0.09) | N7: =((H7-(G7-1))/H7)*(IF(I7<>0,(I7+H7)/H7,1)) | O7: =(N7-(1/6))/(10/6) | P7: 10 | Q7: =IF(F7=1,(((1-((P7-3)/15))*0.5)+0.5),((P7/18)*0.5)) | R7: 0 | S7: 2 | T7: 0 | U7: =IFERROR(T7/S7, 1) | V7: 0 | W7: 3 | X7: =((O7*0.3)+(Q7*0.175)+(R7*0.175)+(U7*0.175)+((1-V7)*0.175))+W7 | Y7: 767378
A8: 46206 | B8: 2 | C8: Mateo | D8: Teval, the Balanced Scale | E8: 3 | F8: 1 | G8: 1 | H8: 4 | I8: 3 | J8: =F8-(1/H8) | K8: =((I8-((H8-1)/H8))-(-5/6))/((5-(5/6))-(-5/6)) | L8: =E8-((E9+E10+E11)/3) | M8: =0.5 + (L8 * 0.09) | N8: =((H8-(G8-1))/H8)*(IF(I8<>0,(I8+H8)/H8,1)) | O8: =(N8-(1/6))/(10/6) | P8: 8 | Q8: =IF(F8=1,(((1-((P8-3)/15))*0.5)+0.5),((P8/18)*0.5)) | R8: 1 | S8: 0 | T8: 0 | U8: =IFERROR(T8/S8, 1) | V8: 0 | W8: 3 | X8: =((O8*0.3)+(Q8*0.175)+(R8*0.175)+(U8*0.175)+((1-V8)*0.175))+W8 | Y8: 773832
A9: 46206 | B9: 2 | C9: Michelle | D9: The Wise Mothman | E9: 2.7 | F9: 0 | G9: 2 | H9: 4 | I9: 0 | J9: =F9-(1/H9) | K9: =((I9-((H9-1)/H9))-(-5/6))/((5-(5/6))-(-5/6)) | L9: =E9-((E8+E10+E11)/3) | M9: =0.5 + (L9 * 0.09) | N9: =((H9-(G9-1))/H9)*(IF(I9<>0,(I9+H9)/H9,1)) | O9: =(N9-(1/6))/(10/6) | P9: 8 | Q9: =IF(F9=1,(((1-((P9-3)/15))*0.5)+0.5),((P9/18)*0.5)) | R9: 1 | S9: 0 | T9: 0 | U9: =IFERROR(T9/S9, 1) | V9: 0 | W9: 2 | X9: =((O9*0.3)+(Q9*0.175)+(R9*0.175)+(U9*0.175)+((1-V9)*0.175))+W9 | Y9: 773832
A10: 46206 | B10: 2 | C10: Becca | D10: Killian, Decisive Mentor | E10: 2.7 | F10: 0 | G10: 2 | H10: 4 | I10: 0 | J10: =F10-(1/H10) | K10: =((I10-((H10-1)/H10))-(-5/6))/((5-(5/6))-(-5/6)) | L10: =E10-((E8+E9+E11)/3) | M10: =0.5 + (L10 * 0.09) | N10: =((H10-(G10-1))/H10)*(IF(I10<>0,(I10+H10)/H10,1)) | O10: =(N10-(1/6))/(10/6) | P10: 8 | Q10: =IF(F10=1,(((1-((P10-3)/15))*0.5)+0.5),((P10/18)*0.5)) | R10: 0 | S10: 0 | T10: 0 | U10: =IFERROR(T10/S10, 1) | V10: 0 | W10: 2 | X10: =((O10*0.3)+(Q10*0.175)+(R10*0.175)+(U10*0.175)+((1-V10)*0.175))+W10 | Y10: 773832
A11: 46206 | B11: 2 | C11: Manny | D11: Galadriel, Light of Valinor | E11: 3.6 | F11: 0 | G11: 2 | H11: 4 | I11: 0 | J11: =F11-(1/H11) | K11: =((I11-((H11-1)/H11))-(-5/6))/((5-(5/6))-(-5/6)) | L11: =E11-((E8+E9+E10)/3) | M11: =0.5 + (L11 * 0.09) | N11: =((H11-(G11-1))/H11)*(IF(I11<>0,(I11+H11)/H11,1)) | O11: =(N11-(1/6))/(10/6) | P11: 8 | Q11: =IF(F11=1,(((1-((P11-3)/15))*0.5)+0.5),((P11/18)*0.5)) | R11: 0 | S11: 0 | T11: 0 | U11: =IFERROR(T11/S11, 1) | V11: 1 | W11: 3 | X11: =((O11*0.3)+(Q11*0.175)+(R11*0.175)+(U11*0.175)+((1-V11)*0.175))+W11 | Y11: 773832
A12: 46206 | B12: 3 | C12: Becca | D12: Killian, Decisive Mentor | E12: 2.5 | F12: 1 | G12: 1 | H12: 4 | I12: 1 | J12: =F12-(1/H12) | K12: =((I12-((H12-1)/H12))-(-5/6))/((5-(5/6))-(-5/6)) | L12: =E12-((E13+E14+E15)/3) | M12: =0.5 + (L12 * 0.09) | N12: =((H12-(G12-1))/H12)*(IF(I12<>0,(I12+H12)/H12,1)) | O12: =(N12-(1/6))/(10/6) | P12: 9 | Q12: =IF(F12=1,(((1-((P12-3)/15))*0.5)+0.5),((P12/18)*0.5)) | R12: 1 | S12: 0 | T12: 0 | U12: =IFERROR(T12/S12, 1) | V12: 0 | W12: 2 | X12: =((O12*0.3)+(Q12*0.175)+(R12*0.175)+(U12*0.175)+((1-V12)*0.175))+W12 | Y12: 774108
A13: 46206 | B13: 3 | C13: Manny | D13: Galadriel, Light of Valinor | E13: 3.3 | F13: 0 | G13: 2 | H13: 4 | I13: 1 | J13: =F13-(1/H13) | K13: =((I13-((H13-1)/H13))-(-5/6))/((5-(5/6))-(-5/6)) | L13: =E13-((E12+E14+E15)/3) | M13: =0.5 + (L13 * 0.09) | N13: =((H13-(G13-1))/H13)*(IF(I13<>0,(I13+H13)/H13,1)) | O13: =(N13-(1/6))/(10/6) | P13: 9 | Q13: =IF(F13=1,(((1-((P13-3)/15))*0.5)+0.5),((P13/18)*0.5)) | R13: 0 | S13: 0 | T13: 0 | U13: =IFERROR(T13/S13, 1) | V13: 1 | W13: 3 | X13: =((O13*0.3)+(Q13*0.175)+(R13*0.175)+(U13*0.175)+((1-V13)*0.175))+W13 | Y13: 774108
A14: 46206 | B14: 3 | C14: Michelle | D14: The Wise Mothman | E14: 2.7 | F14: 0 | G14: 3 | H14: 4 | I14: 1 | J14: =F14-(1/H14) | K14: =((I14-((H14-1)/H14))-(-5/6))/((5-(5/6))-(-5/6)) | L14: =E14-((E12+E13+E15)/3) | M14: =0.5 + (L14 * 0.09) | N14: =((H14-(G14-1))/H14)*(IF(I14<>0,(I14+H14)/H14,1)) | O14: =(N14-(1/6))/(10/6) | P14: 8 | Q14: =IF(F14=1,(((1-((P14-3)/15))*0.5)+0.5),((P14/18)*0.5)) | R14: 1 | S14: 1 | T14: 0 | U14: =IFERROR(T14/S14, 1) | V14: 0 | W14: 2 | X14: =((O14*0.3)+(Q14*0.175)+(R14*0.175)+(U14*0.175)+((1-V14)*0.175))+W14 | Y14: 774108
A15: 46206 | B15: 3 | C15: Mateo | D15: Zurgo Stormrender | E15: 3.9 | F15: 0 | G15: 4 | H15: 4 | I15: 0 | J15: =F15-(1/H15) | K15: =((I15-((H15-1)/H15))-(-5/6))/((5-(5/6))-(-5/6)) | L15: =E15-((E12+E13+E14)/3) | M15: =0.5 + (L15 * 0.09) | N15: =((H15-(G15-1))/H15)*(IF(I15<>0,(I15+H15)/H15,1)) | O15: =(N15-(1/6))/(10/6) | P15: 7 | Q15: =IF(F15=1,(((1-((P15-3)/15))*0.5)+0.5),((P15/18)*0.5)) | R15: 1 | S15: 0 | T15: 0 | U15: =IFERROR(T15/S15, 1) | V15: 0 | W15: 3 | X15: =((O15*0.3)+(Q15*0.175)+(R15*0.175)+(U15*0.175)+((1-V15)*0.175))+W15 | Y15: 774108
A16: 46206 | B16: 4 | C16: Mateo | D16: Ureni of the Unwritten | E16: 3.8 | F16: 1 | G16: 1 | H16: 3 | I16: 2 | J16: =F16-(1/H16) | K16: =((I16-((H16-1)/H16))-(-5/6))/((5-(5/6))-(-5/6)) | L16: =E16-((E17+E18)/2) | M16: =0.5 + (L16 * 0.09) | N16: =((H16-(G16-1))/H16)*(IF(I16<>0,(I16+H16)/H16,1)) | O16: =(N16-(1/6))/(10/6) | P16: 8 | Q16: =IF(F16=1,(((1-((P16-3)/15))*0.5)+0.5),((P16/18)*0.5)) | R16: 1 | S16: 0 | T16: 0 | U16: =IFERROR(T16/S16, 1) | V16: 0 | W16: 3 | X16: =((O16*0.3)+(Q16*0.175)+(R16*0.175)+(U16*0.175)+((1-V16)*0.175))+W16 | Y16: 774418
A17: 46206 | B17: 4 | C17: Becca | D17: Killian, Decisive Mentor | E17: 2.9 | F17: 0 | G17: 2 | H17: 3 | I17: 0 | J17: =F17-(1/H17) | K17: =((I17-((H17-1)/H17))-(-5/6))/((5-(5/6))-(-5/6)) | L17: =E17-((E16+E18)/2) | M17: =0.5 + (L17 * 0.09) | N17: =((H17-(G17-1))/H17)*(IF(I17<>0,(I17+H17)/H17,1)) | O17: =(N17-(1/6))/(10/6) | P17: 8 | Q17: =IF(F17=1,(((1-((P17-3)/15))*0.5)+0.5),((P17/18)*0.5)) | R17: 0 | S17: 1 | T17: 0 | U17: =IFERROR(T17/S17, 1) | V17: 0 | W17: 2 | X17: =((O17*0.3)+(Q17*0.175)+(R17*0.175)+(U17*0.175)+((1-V17)*0.175))+W17 | Y17: 774418
A18: 46206 | B18: 4 | C18: Manny | D18: Zada, Hedron Grinder | E18: 2.5 | F18: 0 | G18: 2 | H18: 3 | I18: 0 | J18: =F18-(1/H18) | K18: =((I18-((H18-1)/H18))-(-5/6))/((5-(5/6))-(-5/6)) | L18: =E18-((E16+E17)/2) | M18: =0.5 + (L18 * 0.09) | N18: =((H18-(G18-1))/H18)*(IF(I18<>0,(I18+H18)/H18,1)) | O18: =(N18-(1/6))/(10/6) | P18: 8 | Q18: =IF(F18=1,(((1-((P18-3)/15))*0.5)+0.5),((P18/18)*0.5)) | R18: 0 | S18: 1 | T18: 0 | U18: =IFERROR(T18/S18, 1) | V18: 0 | W18: 2 | X18: =((O18*0.3)+(Q18*0.175)+(R18*0.175)+(U18*0.175)+((1-V18)*0.175))+W18 | Y18: 774418
A19: 46211 | B19: 5 | C19: Becca | D19: Ms. Bumbleflower | E19: 2.5 | F19: 1 | G19: 1 | H19: 4 | I19: 1 | J19: =F19-(1/H19) | K19: =((I19-((H19-1)/H19))-(-5/6))/((5-(5/6))-(-5/6)) | L19: =E19-((E20+E21+E22)/3) | M19: =0.5 + (L19 * 0.09) | N19: =((H19-(G19-1))/H19)*(IF(I19<>0,(I19+H19)/H19,1)) | O19: =(N19-(1/6))/(10/6) | P19: 14 | Q19: =IF(F19=1,(((1-((P19-3)/15))*0.5)+0.5),((P19/18)*0.5)) | R19: 1 | S19: 3 | T19: 2 | U19: =IFERROR(T19/S19, 1) | V19: 0 | W19: 2 | X19: =((O19*0.3)+(Q19*0.175)+(R19*0.175)+(U19*0.175)+((1-V19)*0.175))+W19 | Y19: 787397
A20: 46211 | B20: 5 | C20: Mateo | D20: Captain America, Team Leader | E20: 3.7 | F20: 0 | G20: 2 | H20: 4 | I20: 2 | J20: =F20-(1/H20) | K20: =((I20-((H20-1)/H20))-(-5/6))/((5-(5/6))-(-5/6)) | L20: =E20-((E19+E21+E22)/3) | M20: =0.5 + (L20 * 0.09) | N20: =((H20-(G20-1))/H20)*(IF(I20<>0,(I20+H20)/H20,1)) | O20: =(N20-(1/6))/(10/6) | P20: 14 | Q20: =IF(F20=1,(((1-((P20-3)/15))*0.5)+0.5),((P20/18)*0.5)) | R20: 1 | S20: 5 | T20: 2 | U20: =IFERROR(T20/S20, 1) | V20: 0 | W20: 3 | X20: =((O20*0.3)+(Q20*0.175)+(R20*0.175)+(U20*0.175)+((1-V20)*0.175))+W20 | Y20: 787397
A21: 46211 | B21: 5 | C21: Ryan | D21: Rootha, Mastering the Moment | E21: 3.7 | F21: 0 | G21: 3 | H21: 4 | I21: 0 | J21: =F21-(1/H21) | K21: =((I21-((H21-1)/H21))-(-5/6))/((5-(5/6))-(-5/6)) | L21: =E21-((E19+E20+E22)/3) | M21: =0.5 + (L21 * 0.09) | N21: =((H21-(G21-1))/H21)*(IF(I21<>0,(I21+H21)/H21,1)) | O21: =(N21-(1/6))/(10/6) | P21: 14 | Q21: =IF(F21=1,(((1-((P21-3)/15))*0.5)+0.5),((P21/18)*0.5)) | R21: 1 | S21: 5 | T21: 3 | U21: =IFERROR(T21/S21, 1) | V21: 0 | W21: 3 | X21: =((O21*0.3)+(Q21*0.175)+(R21*0.175)+(U21*0.175)+((1-V21)*0.175))+W21 | Y21: 787397
A22: 46211 | B22: 5 | C22: Manny | D22: Kruphix, God of Horizons | E22: 2.7 | F22: 0 | G22: 4 | H22: 4 | I22: 0 | J22: =F22-(1/H22) | K22: =((I22-((H22-1)/H22))-(-5/6))/((5-(5/6))-(-5/6)) | L22: =E22-((E19+E20+E21)/3) | M22: =0.5 + (L22 * 0.09) | N22: =((H22-(G22-1))/H22)*(IF(I22<>0,(I22+H22)/H22,1)) | O22: =(N22-(1/6))/(10/6) | P22: 12 | Q22: =IF(F22=1,(((1-((P22-3)/15))*0.5)+0.5),((P22/18)*0.5)) | R22: 1 | S22: 1 | T22: 1 | U22: =IFERROR(T22/S22, 1) | V22: 0 | W22: 2 | X22: =((O22*0.3)+(Q22*0.175)+(R22*0.175)+(U22*0.175)+((1-V22)*0.175))+W22 | Y22: 787397
A23: 46220 | B23: 6 | C23: Mateo | D23: Kratos, God of War | E23: 2 | F23: 1 | G23: 1 | H23: 5 | I23: 2 | J23: =F23-(1/H23) | K23: =((I23-((H23-1)/H23))-(-5/6))/((5-(5/6))-(-5/6)) | L23: =E23-((E24+E25+E26+E27)/4) | M23: =0.5 + (L23 * 0.09) | N23: =((H23-(G23-1))/H23)*(IF(I23<>0,(I23+H23)/H23,1)) | O23: =(N23-(1/6))/(10/6) | P23: 9 | Q23: =IF(F23=1,(((1-((P23-3)/15))*0.5)+0.5),((P23/18)*0.5)) | R23: 1 | S23: 0 | T23: 0 | U23: =IFERROR(T23/S23, 1) | V23: 0 | W23: 2 | X23: =((O23*0.3)+(Q23*0.175)+(R23*0.175)+(U23*0.175)+((1-V23)*0.175))+W23 | Y23: 823975
A24: 46220 | B24: 6 | C24: Joseph | D24: Ultima, Origin of Oblivion | E24: 3 | F24: 0 | G24: 2 | H24: 5 | I24: 2 | J24: =F24-(1/H24) | K24: =((I24-((H24-1)/H24))-(-5/6))/((5-(5/6))-(-5/6)) | L24: =E24-((E23+E25+E26+E27)/4) | M24: =0.5 + (L24 * 0.09) | N24: =((H24-(G24-1))/H24)*(IF(I24<>0,(I24+H24)/H24,1)) | O24: =(N24-(1/6))/(10/6) | P24: 9 | Q24: =IF(F24=1,(((1-((P24-3)/15))*0.5)+0.5),((P24/18)*0.5)) | R24: 1 | S24: 0 | T24: 0 | U24: =IFERROR(T24/S24, 1) | V24: 0 | W24: 3 | X24: =((O24*0.3)+(Q24*0.175)+(R24*0.175)+(U24*0.175)+((1-V24)*0.175))+W24 | Y24: 823975
A25: 46220 | B25: 6 | C25: Manny | D25: Kruphix, God of Horizons | E25: 2.6 | F25: 0 | G25: 3 | H25: 5 | I25: 0 | J25: =F25-(1/H25) | K25: =((I25-((H25-1)/H25))-(-5/6))/((5-(5/6))-(-5/6)) | L25: =E25-((E23+E24+E26+E27)/4) | M25: =0.5 + (L25 * 0.09) | N25: =((H25-(G25-1))/H25)*(IF(I25<>0,(I25+H25)/H25,1)) | O25: =(N25-(1/6))/(10/6) | P25: 8 | Q25: =IF(F25=1,(((1-((P25-3)/15))*0.5)+0.5),((P25/18)*0.5)) | R25: 0 | S25: 0 | T25: 0 | U25: =IFERROR(T25/S25, 1) | V25: 0 | W25: 2 | X25: =((O25*0.3)+(Q25*0.175)+(R25*0.175)+(U25*0.175)+((1-V25)*0.175))+W25 | Y25: 823975
A26: 46220 | B26: 6 | C26: Ryan | D26: Ashling, The Limitless | E26: 3.5 | F26: 0 | G26: 4 | H26: 5 | I26: 0 | J26: =F26-(1/H26) | K26: =((I26-((H26-1)/H26))-(-5/6))/((5-(5/6))-(-5/6)) | L26: =E26-((E23+E24+E25+E27)/4) | M26: =0.5 + (L26 * 0.09) | N26: =((H26-(G26-1))/H26)*(IF(I26<>0,(I26+H26)/H26,1)) | O26: =(N26-(1/6))/(10/6) | P26: 8 | Q26: =IF(F26=1,(((1-((P26-3)/15))*0.5)+0.5),((P26/18)*0.5)) | R26: 0 | S26: 0 | T26: 0 | U26: =IFERROR(T26/S26, 1) | V26: 0 | W26: 3 | X26: =((O26*0.3)+(Q26*0.175)+(R26*0.175)+(U26*0.175)+((1-V26)*0.175))+W26 | Y26: 823975
A27: 46220 | B27: 6 | C27: Kristy | D27: Doctor Doom, King of Latveria | E27: 2 | F27: 0 | G27: 5 | H27: 5 | I27: 0 | J27: =F27-(1/H27) | K27: =((I27-((H27-1)/H27))-(-5/6))/((5-(5/6))-(-5/6)) | L27: =E27-((E23+E24+E25+E26)/4) | M27: =0.5 + (L27 * 0.09) | N27: =((H27-(G27-1))/H27)*(IF(I27<>0,(I27+H27)/H27,1)) | O27: =(N27-(1/6))/(10/6) | P27: 8 | Q27: =IF(F27=1,(((1-((P27-3)/15))*0.5)+0.5),((P27/18)*0.5)) | R27: 0 | S27: 0 | T27: 0 | U27: =IFERROR(T27/S27, 1) | V27: 0 | W27: 2 | X27: =((O27*0.3)+(Q27*0.175)+(R27*0.175)+(U27*0.175)+((1-V27)*0.175))+W27 | Y27: 823975
A28: 46220 | B28: 7 | C28: Manny | D28: Aragorn, the Uniter | E28: 3.5 | F28: 1 | G28: 1 | H28: 4 | I28: 2 | J28: =F28-(1/H28) | K28: =((I28-((H28-1)/H28))-(-5/6))/((5-(5/6))-(-5/6)) | L28: =E28-((E29+E30+E31)/3) | M28: =0.5 + (L28 * 0.09) | N28: =((H28-(G28-1))/H28)*(IF(I28<>0,(I28+H28)/H28,1)) | O28: =(N28-(1/6))/(10/6) | P28: 8 | Q28: =IF(F28=1,(((1-((P28-3)/15))*0.5)+0.5),((P28/18)*0.5)) | R28: 1 | S28: 0 | T28: 0 | U28: =IFERROR(T28/S28, 1) | V28: 0 | W28: 3 | X28: =((O28*0.3)+(Q28*0.175)+(R28*0.175)+(U28*0.175)+((1-V28)*0.175))+W28 | Y28: 824881
A29: 46220 | B29: 7 | C29: Ryan | D29: Arna Kennerud, Skycaptain | E29: 2 | F29: 0 | G29: 2 | H29: 4 | I29: 1 | J29: =F29-(1/H29) | K29: =((I29-((H29-1)/H29))-(-5/6))/((5-(5/6))-(-5/6)) | L29: =E29-((E28+E30+E31)/3) | M29: =0.5 + (L29 * 0.09) | N29: =((H29-(G29-1))/H29)*(IF(I29<>0,(I29+H29)/H29,1)) | O29: =(N29-(1/6))/(10/6) | P29: 8 | Q29: =IF(F29=1,(((1-((P29-3)/15))*0.5)+0.5),((P29/18)*0.5)) | R29: 1 | S29: 0 | T29: 0 | U29: =IFERROR(T29/S29, 1) | V29: 0 | W29: 2 | X29: =((O29*0.3)+(Q29*0.175)+(R29*0.175)+(U29*0.175)+((1-V29)*0.175))+W29 | Y29: 824881
A30: 46220 | B30: 7 | C30: Mateo | D30: Captain America, Team Leader | E30: 3.7 | F30: 0 | G30: 2 | H30: 4 | I30: 0 | J30: =F30-(1/H30) | K30: =((I30-((H30-1)/H30))-(-5/6))/((5-(5/6))-(-5/6)) | L30: =E30-((E28+E29+E31)/3) | M30: =0.5 + (L30 * 0.09) | N30: =((H30-(G30-1))/H30)*(IF(I30<>0,(I30+H30)/H30,1)) | O30: =(N30-(1/6))/(10/6) | P30: 8 | Q30: =IF(F30=1,(((1-((P30-3)/15))*0.5)+0.5),((P30/18)*0.5)) | R30: 0 | S30: 0 | T30: 0 | U30: =IFERROR(T30/S30, 1) | V30: 0 | W30: 3 | X30: =((O30*0.3)+(Q30*0.175)+(R30*0.175)+(U30*0.175)+((1-V30)*0.175))+W30 | Y30: 824881
A31: 46220 | B31: 7 | C31: Becca | D31: Ms. Bumbleflower | E31: 2.8 | F31: 0 | G31: 4 | H31: 4 | I31: 0 | J31: =F31-(1/H31) | K31: =((I31-((H31-1)/H31))-(-5/6))/((5-(5/6))-(-5/6)) | L31: =E31-((E28+E29+E30)/3) | M31: =0.5 + (L31 * 0.09) | N31: =((H31-(G31-1))/H31)*(IF(I31<>0,(I31+H31)/H31,1)) | O31: =(N31-(1/6))/(10/6) | P31: 8 | Q31: =IF(F31=1,(((1-((P31-3)/15))*0.5)+0.5),((P31/18)*0.5)) | R31: 0 | S31: 0 | T31: 0 | U31: =IFERROR(T31/S31, 1) | V31: 0 | W31: 2 | X31: =((O31*0.3)+(Q31*0.175)+(R31*0.175)+(U31*0.175)+((1-V31)*0.175))+W31 | Y31: 824881
A32: 46225 | B32: 8 | C32: Manny | D32: Galadriel, Light of Valinor | E32: 3.4 | F32: 1 | G32: 1 | H32: 3 | I32: 2 | J32: =F32-(1/H32) | K32: =((I32-((H32-1)/H32))-(-5/6))/((5-(5/6))-(-5/6)) | L32: =E32-((E33+E34)/2) | M32: =0.5 + (L32 * 0.09) | N32: =((H32-(G32-1))/H32)*(IF(I32<>0,(I32+H32)/H32,1)) | O32: =(N32-(1/6))/(10/6) | P32: 9 | Q32: =IF(F32=1,(((1-((P32-3)/15))*0.5)+0.5),((P32/18)*0.5)) | R32: 1 | S32: 0 | T32: 0 | U32: =IFERROR(T32/S32, 1) | V32: 0 | W32: 3 | X32: =((O32*0.3)+(Q32*0.175)+(R32*0.175)+(U32*0.175)+((1-V32)*0.175))+W32 | Y32: 848075
A33: 46225 | B33: 8 | C33: Becca | D33: Eshki, Temur's Roar (Manny's) | E33: 2 | F33: 0 | G33: 2 | H33: 3 | I33: 0 | J33: =F33-(1/H33) | K33: =((I33-((H33-1)/H33))-(-5/6))/((5-(5/6))-(-5/6)) | L33: =E33-((E32+E34)/2) | M33: =0.5 + (L33 * 0.09) | N33: =((H33-(G33-1))/H33)*(IF(I33<>0,(I33+H33)/H33,1)) | O33: =(N33-(1/6))/(10/6) | P33: 9 | Q33: =IF(F33=1,(((1-((P33-3)/15))*0.5)+0.5),((P33/18)*0.5)) | R33: 0 | S33: 0 | T33: 0 | U33: =IFERROR(T33/S33, 1) | V33: 0 | W33: 2 | X33: =((O33*0.3)+(Q33*0.175)+(R33*0.175)+(U33*0.175)+((1-V33)*0.175))+W33 | Y33: 848075
